Workbook

Sheet Teams
B1: Kevin | D1: Marcelo | F1: Emiliano | H1: Roy | J1: Beto | L1: Steve
A2: # | B2: Player | C2: POS | D2: Player | E2: POS | F2: Player | G2: POS | H2: Player | I2: POS | J2: Player | K2: POS | L2: Player | M2: POS
A3: 1 | B3: {=_xlfn._xlws.FILTER(ADPs!$B:$B,ADPs!$G:$G=Teams!B1)} -> #VALUE! | C3: {=_xlfn._xlws.FILTER(ADPs!$C:$C,ADPs!$G:$G=Teams!B1)} -> #VALUE! | D3: {=_xlfn._xlws.FILTER(ADPs!$B:$B,ADPs!$G:$G=Teams!D1)} -> #VALUE! | E3: {=_xlfn._xlws.FILTER(ADPs!$C:$C,ADPs!$G:$G=Teams!D1)} -> #VALUE! | F3: {=_xlfn._xlws.FILTER(ADPs!$B:$B,ADPs!$G:$G=Teams!F1)} -> #VALUE! | G3: {=_xlfn._xlws.FILTER(ADPs!$C:$C,ADPs!$G:$G=Teams!F1)} -> #VALUE! | H3: {=_xlfn._xlws.FILTER(ADPs!$B:$B,ADPs!$G:$G=Teams!H1)} -> #VALUE! | I3: {=_xlfn._xlws.FILTER(ADPs!$C:$C,ADPs!$G:$G=Teams!H1)} -> #VALUE! | J3: {=_xlfn._xlws.FILTER(ADPs!$B:$B,ADPs!$G:$G=Teams!J1)} -> #VALUE! | K3: {=_xlfn._xlws.FILTER(ADPs!$C:$C,ADPs!$G:$G=Teams!J1)} -> #VALUE! | L3: {=_xlfn._xlws.FILTER(ADPs!$B:$B,ADPs!$G:$G=Teams!L1)} -> #VALUE! | M3: {=_xlfn._xlws.FILTER(ADPs!$C:$C,ADPs!$G:$G=Teams!L1)} -> #VALUE!
A4: 2
A5: 3
A6: 4
A7: 5
A8: 6
A9: 7
A10: 8
A11: 9
A12: 10
A13: 11
A14: 12
A15: 13
... A20: 18
B22: QB | C22: =+COUNTIF(C$3:C$20, $B22) -> 0 | D22: QB | E22: =+COUNTIF(E$3:E$20, $B22) -> 0 | F22: QB | G22: =+COUNTIF(G$3:G$20, $B22) -> 0 | H22: QB | I22: =+COUNTIF(I$3:I$20, $B22) -> 0 | J22: QB | K22: =+COUNTIF(K$3:K$20, $B22) -> 0 | L22: QB | M22: =+COUNTIF(M$3:M$20, $B22) -> 0
B23: RB | C23: =+COUNTIF(C$3:C$20, $B23) -> 0 | D23: RB | E23: =+COUNTIF(E$3:E$20, $B23) -> 0 | F23: RB | G23: =+COUNTIF(G$3:G$20, $B23) -> 0 | H23: RB | I23: =+COUNTIF(I$3:I$20, $B23) -> 0 | J23: RB | K23: =+COUNTIF(K$3:K$20, $B23) -> 0 | L23: RB | M23: =+COUNTIF(M$3:M$20, $B23) -> 0
B24: WR | C24: =+COUNTIF(C$3:C$20, $B24) -> 0 | D24: WR | E24: =+COUNTIF(E$3:E$20, $B24) -> 0 | F24: WR | G24: =+COUNTIF(G$3:G$20, $B24) -> 0 | H24: WR | I24: =+COUNTIF(I$3:I$20, $B24) -> 0 | J24: WR | K24: =+COUNTIF(K$3:K$20, $B24) -> 0 | L24: WR | M24: =+COUNTIF(M$3:M$20, $B24) -> 0
B25: TE | C25: =+COUNTIF(C$3:C$20, $B25) -> 0 | D25: TE | E25: =+COUNTIF(E$3:E$20, $B25) -> 0 | F25: TE | G25: =+COUNTIF(G$3:G$20, $B25) -> 0 | H25: TE | I25: =+COUNTIF(I$3:I$20, $B25) -> 0 | J25: TE | K25: =+COUNTIF(K$3:K$20, $B25) -> 0 | L25: TE | M25: =+COUNTIF(M$3:M$20, $B25) -> 0
B26: DS | C26: =+COUNTIF(C$3:C$20, $B26) -> 0 | D26: DS | E26: =+COUNTIF(E$3:E$20, $B26) -> 0 | F26: DS | G26: =+COUNTIF(G$3:G$20, $B26) -> 0 | H26: DS | I26: =+COUNTIF(I$3:I$20, $B26) -> 0 | J26: DS | K26: =+COUNTIF(K$3:K$20, $B26) -> 0 | L26: DS | M26: =+COUNTIF(M$3:M$20, $B26) -> 0

Sheet ADPs
A1: NFL | B1: Player | C1: Pos | D1: Team | E1: Bye | F1: POS1 | G1: Taken
A2: 1 | B2: Ja'Marr Chase | C2: WR | D2: CIN | E2: 10 | F2: WR1
A3: 2 | B3: Bijan Robinson | C3: RB | D3: ATL | E3: 5 | F3: RB1
A4: 3 | B4: CeeDee Lamb | C4: WR | D4: DAL | E4: 10 | F4: WR2
A5: 4 | B5: Justin Jefferson | C5: WR | D5: MIN | E5: 6 | F5: WR3
A6: 5 | B6: Jahmyr Gibbs | C6: RB | D6: DET | E6: 8 | F6: RB2
A7: 6 | B7: Saquon Barkley | C7: RB | D7: PHI | E7: 9 | F7: RB3
A8: 7 | B8: Malik Nabers | C8: WR | D8: NYG | E8: 14 | F8: WR4
A9: 8 | B9: Amon-Ra St. Brown | C9: WR | D9: DET | E9: 8 | F9: WR5
A10: 9 | B10: Nico Collins | C10: WR | D10: HOU | E10: 6 | F10: WR6
A11: 10 | B11: Puka Nacua | C11: WR | D11: LAR | E11: 8 | F11: WR7
A12: 11 | B12: Christian McCaffrey | C12: RB | D12: SF | E12: 14 | F12: RB4
A13: 12 | B13: Brian Thomas Jr. | C13: WR | D13: JAC | E13: 8 | F13: WR8
... A311: 310 | B311: Sincere McCormick | C311: RB | D311: LV | E311: 8 | F311: RB92
A312: 311 | B312: Amari Cooper | C312: WR | D312: FA | E312: - | F312: WR109
A313: 312 | B313: Tyler Higbee | C313: TE | D313: LAR | E313: 8 | F313: TE39
A314: 313 | B314: Arizona Cardinals | C314: DS | D314: ARI | E314: 8 | F314: DST21
A315: 314 | B315: Troy Franklin | C315: WR | D315: DEN | E315: 12 | F315: WR110
A316: 315 | B316: Jermaine Burton | C316: WR | D316: CIN | E316: 10 | F316: WR111
A317: 316 | B317: Damien Martinez | C317: RB | D317: SEA | E317: 8 | F317: RB93
A318: 317 | B318: Chris Brooks | C318: RB | D318: GB | E318: 5 | F318: RB94
A319: 318 | B319: Phil Mafah | C319: RB | D319: DAL | E319: 10 | F319: RB95
A320: 319 | B320: Oronde Gadsden II | C320: TE | D320: LAC | E320: 12 | F320: TE40
A321: 320 | B321: Shedeur Sanders | C321: QB | D321: CLE | E321: 9 | F321: QB35
A322: 321 | B322: Samaje Perine | C322: RB | D322: CIN | E322: 10 | F322: RB96
A323: 322 | B323: Tez Johnson | C323: WR | D323: TB | E323: 9 | F323: WR112
A324: 323 | B324: Ty Chandler | C324: RB | D324: MIN | E324: 6 | F324: RB97
... A340: 339 | B340: A.J. Dillon | C340: RB | D340: PHI | E340: 9 | F340: RB100
A341: 340 | B341: Gabe Davis | C341: WR | D341: FA | E341: - | F341: WR118
A342: 341 | B342: Zack Moss | C342: RB | D342: FA | E342: - | F342: RB101
A343: 342 | B343: KeAndre Lambert-Smith | C343: WR | D343: LAC | E343: 12 | F343: WR119
A344: 343 | B344: Brandon McManus | C344: K2 | D344: GB | E344: 5 | F344: K21
A345: 344 | B345: Tai Felton | C345: WR | D345: MIN | E345: 6 | F345: WR120
A346: 345 | B346: New York Giants | C346: DS | D346: NYG | E346: 14 | F346: DST23
A347: 346 | B347: Jaylin Lane | C347: WR | D347: WAS | E347: 12 | F347: WR121
A348: 347 | B348: AJ Barner | C348: TE | D348: SEA | E348: 8 | F348: TE44
A349: 348 | B349: Michael Mayer | C349: TE | D349: LV | E349: 8 | F349: TE45
A350: 349 | B350: Isaiah Bond | C350: WR | D350: CLE | E350: 9 | F350: WR122
A351: 350 | B351: John Metchie III | C351: WR | D351: PHI | E351: 9 | F351: WR123
A352: 351 | B352: Marquez Valdes-Scantling | C352: WR | D352: SEA | E352: 8 | F352: WR124
...
