Workbook

Sheet Teams
B1: Kevin | D1: Marcelo | F1: Emiliano | H1: Roy | J1: Beto | L1: Steve
A2: # | B2: Player | C2: POS | D2: Player | E2: POS | F2: Player | G2: POS | H2: Player | I2: POS | J2: Player | K2: POS | L2: Player | M2: POS
A3: 1 | B3: {=_xlfn._xlws.FILTER(ADPs!$C:$C,ADPs!$J:$J=Teams!B1)} -> Ja'Marr Chase | C3: {=_xlfn._xlws.FILTER(ADPs!$D:$D,ADPs!$J:$J=Teams!B1)} -> WR | D3: {=_xlfn._xlws.FILTER(ADPs!$C:$C,ADPs!$J:$J=Teams!D1)} -> Bijan Robinson | E3: {=_xlfn._xlws.FILTER(ADPs!$D:$D,ADPs!$J:$J=Teams!D1)} -> RB | F3: {=_xlfn._xlws.FILTER(ADPs!$C:$C,ADPs!$J:$J=Teams!F1)} -> Jahmyr Gibbs | G3: {=_xlfn._xlws.FILTER(ADPs!$D:$D,ADPs!$J:$J=Teams!F1)} -> RB | H3: {=_xlfn._xlws.FILTER(ADPs!$C:$C,ADPs!$J:$J=Teams!H1)} -> Jaxon Smith-Njigba | I3: {=_xlfn._xlws.FILTER(ADPs!$D:$D,ADPs!$J:$J=Teams!H1)} -> WR | J3: {=_xlfn._xlws.FILTER(ADPs!$C:$C,ADPs!$J:$J=Teams!J1)} -> Puka Nacua | K3: {=_xlfn._xlws.FILTER(ADPs!$D:$D,ADPs!$J:$J=Teams!J1)} -> WR | L3: {=_xlfn._xlws.FILTER(ADPs!$C:$C,ADPs!$J:$J=Teams!L1)} -> Amon-Ra St. Brown | M3: {=_xlfn._xlws.FILTER(ADPs!$D:$D,ADPs!$J:$J=Teams!L1)} -> WR
A4: 2 | B4: Justin Jefferson | C4: WR | D4: Christian McCaffrey | E4: RB | F4: CeeDee Lamb | G4: WR | H4: Kenneth Walker III | I4: RB | J4: James Cook III | K4: RB | L4: Jonathan Taylor | M4: RB
A5: 3 | B5: Omarion Hampton | C5: RB | D5: A.J. Brown | E5: WR | F5: De'Von Achane | G5: RB | H5: Josh Allen | I5: QB | J5: Chase Brown | K5: RB | L5: Drake London | M5: WR
A6: 4 | B6: DeVonta Smith | C6: WR | D6: Nico Collins | E6: WR | F6: Ladd McConkey | G6: WR | H6: Zay Flowers | I6: WR | J6: Trey McBride | K6: TE | L6: George Pickens | M6: WR
A7: 5 | B7: Ashton Jeanty | C7: RB | D7: Chris Olave | E7: WR | F7: Derrick Henry | G7: RB | H7: Garrett Wilson | I7: WR | J7: Rashee Rice | K7: WR | L7: Brock Bowers | M7: TE
A8: 6 | B8: Javonte Williams | C8: RB | D8: Malik Nabers | E8: WR | F8: Drake Maye | G8: QB | H8: Tetairoa McMillan | I8: WR | J8: Emeka Egbuka | K8: WR | L8: Breece Hall | M8: RB
A9: 7 | B9: Jadarian Price | C9: RB | D9: Jeremiyah Love | E9: RB | F9: Colston Loveland | G9: TE | H9: Kyren Williams | I9: RB | J9: Bucky Irving | K9: RB | L9: Lamar Jackson | M9: QB
A10: 8 | B10: Justin Herbert | C10: QB | D10: Jaylen Waddle | E10: WR | F10: Travis Etienne Jr. | G10: RB | H10: Davante Adams | I10: WR | J10: Cam Skattebo | K10: RB | L10: Tee Higgins | M10: WR
A11: 9 | B11: Tucker Kraft | C11: TE | D11: DJ Moore | E11: WR | F11: Rome Odunze | G11: WR | H11: TreVeyon Henderson | I11: RB | J11: Quinshon Judkins | K11: RB | L11: Joe Burrow | M11: QB
A12: 10 | B12: George Kittle | C12: TE | D12: D'Andre Swift | E12: RB | F12: Michael Pittman Jr. | G12: WR | H12: Kyle Pitts Sr. | I12: TE
A13: 11 | D13: Tyler Warren | E13: TE | H13: Blake Corum | I13: RB
A14: 12
A15: 13
A16: 14
A17: 15
A18: 16
A19: 17
A20: 18
B22: QB | C22: =+COUNTIF(C$3:C$20, $B22) -> 1 | D22: QB | E22: =+COUNTIF(E$3:E$20, $B22) -> 0 | F22: QB | G22: =+COUNTIF(G$3:G$20, $B22) -> 1 | H22: QB | I22: =+COUNTIF(I$3:I$20, $B22) -> 1 | J22: QB | K22: =+COUNTIF(K$3:K$20, $B22) -> 0 | L22: QB | M22: =+COUNTIF(M$3:M$20, $B22) -> 2
B23: RB | C23: =+COUNTIF(C$3:C$20, $B23) -> 4 | D23: RB | E23: =+COUNTIF(E$3:E$20, $B23) -> 4 | F23: RB | G23: =+COUNTIF(G$3:G$20, $B23) -> 4 | H23: RB | I23: =+COUNTIF(I$3:I$20, $B23) -> 4 | J23: RB | K23: =+COUNTIF(K$3:K$20, $B23) -> 5 | L23: RB | M23: =+COUNTIF(M$3:M$20, $B23) -> 2
B24: WR | C24: =+COUNTIF(C$3:C$20, $B24) -> 3 | D24: WR | E24: =+COUNTIF(E$3:E$20, $B24) -> 6 | F24: WR | G24: =+COUNTIF(G$3:G$20, $B24) -> 4 | H24: WR | I24: =+COUNTIF(I$3:I$20, $B24) -> 5 | J24: WR | K24: =+COUNTIF(K$3:K$20, $B24) -> 3 | L24: WR | M24: =+COUNTIF(M$3:M$20, $B24) -> 4
B25: TE | C25: =+COUNTIF(C$3:C$20, $B25) -> 2 | D25: TE | E25: =+COUNTIF(E$3:E$20, $B25) -> 1 | F25: TE | G25: =+COUNTIF(G$3:G$20, $B25) -> 1 | H25: TE | I25: =+COUNTIF(I$3:I$20, $B25) -> 1 | J25: TE | K25: =+COUNTIF(K$3:K$20, $B25) -> 1 | L25: TE | M25: =+COUNTIF(M$3:M$20, $B25) -> 1
B26: DS | C26: =+COUNTIF(C$3:C$20, $B26) -> 0 | D26: DS | E26: =+COUNTIF(E$3:E$20, $B26) -> 0 | F26: DS | G26: =+COUNTIF(G$3:G$20, $B26) -> 0 | H26: DS | I26: =+COUNTIF(I$3:I$20, $B26) -> 0 | J26: DS | K26: =+COUNTIF(K$3:K$20, $B26) -> 0 | L26: DS | M26: =+COUNTIF(M$3:M$20, $B26) -> 0

Sheet ADPs
A1: NFL | B1: Key | C1: Player | D1: Pos | E1: Team | F1: Bye | G1: UPSIDE | H1: BUST | I1: POS1 | J1: Taken
A2: 4 | B2: x | C2: Bijan Robinson | D2: RB | E2: ATL | F2: 11 | G2: 5 out of 5 | H2: 1 out of 5 | I2: RB2 | J2: Marcelo
A3: 2 | B3: x | C3: Jahmyr Gibbs | D3: RB | E3: DET | F3: 6 | G3: 5 out of 5 | H3: 1 out of 5 | I3: RB1 | J3: Emiliano
A4: 1 | B4: x | C4: Ja'Marr Chase | D4: WR | E4: CIN | F4: 6 | G4: 5 out of 5 | H4: 1 out of 5 | I4: WR1 | J4: Kevin
A5: 5 | B5: x | C5: Jaxon Smith-Njigba | D5: WR | E5: SEA | F5: 11 | G5: 5 out of 5 | H5: 2 out of 5 | I5: WR3 | J5: Roy
A6: 8 | B6: x | C6: Christian McCaffrey | D6: RB | E6: SF | F6: 8 | G6: 4 out of 5 | H6: 4 out of 5 | I6: RB3 | J6: Marcelo
A7: 9 | B7: x | C7: Justin Jefferson | D7: WR | E7: MIN | F7: 6 | G7: 5 out of 5 | H7: 2 out of 5 | I7: WR6 | J7: Kevin
A8: 3 | C8: Puka Nacua | D8: WR | E8: LAR | F8: 11 | G8: 5 out of 5 | H8: 2 out of 5 | I8: WR2 | J8: Beto
A9: 6 | B9: x | C9: Amon-Ra St. Brown | D9: WR | E9: DET | F9: 6 | G9: 5 out of 5 | H9: 1 out of 5 | I9: WR4 | J9: Steve
A10: 7 | C10: CeeDee Lamb | D10: WR | E10: DAL | F10: 14 | G10: 4 out of 5 | H10: 2 out of 5 | I10: WR5 | J10: Emiliano
A11: 25 | B11: x | C11: Omarion Hampton | D11: RB | E11: LAC | F11: 7 | G11: 5 out of 5 | H11: 2 out of 5 | I11: RB10 | J11: Kevin
A12: 10 | C12: Jonathan Taylor | D12: RB | E12: IND | F12: 13 | G12: 4 out of 5 | H12: 3 out of 5 | I12: RB4 | J12: Steve
A13: 13 | C13: James Cook III | D13: RB | E13: BUF | F13: 7 | G13: 5 out of 5 | H13: 1 out of 5 | I13: RB5 | J13: Beto
A14: 22 | B14: x | C14: Saquon Barkley | D14: RB | E14: PHI | F14: 10 | G14: 4 out of 5 | H14: 4 out of 5 | I14: RB8 | J14: Saquon
A15: 21 | B15: x | C15: DeVonta Smith | D15: WR | E15: PHI | F15: 10 | G15: 4 out of 5 | H15: 2 out of 5 | I15: WR12 | J15: Kevin
A16: 12 | C16: A.J. Brown | D16: WR | E16: NE | F16: 11 | G16: 5 out of 5 | H16: 2 out of 5 | I16: WR8 | J16: Marcelo
A17: 11 | B17: x | C17: Drake London | D17: WR | E17: ATL | F17: 11 | G17: 4 out of 5 | H17: 3 out of 5 | I17: WR7 | J17: Steve
A18: 14 | C18: Nico Collins | D18: WR | E18: HOU | F18: 8 | G18: 4 out of 5 | H18: 2 out of 5 | I18: WR9 | J18: Marcelo
A19: 15 | C19: Chase Brown | D19: RB | E19: CIN | F19: 6 | G19: 5 out of 5 | H19: 2 out of 5 | I19: RB6 | J19: Beto
A20: 28 | B20: x | C20: Ashton Jeanty | D20: RB | E20: LV | F20: 13 | G20: 4 out of 5 | H20: 4 out of 5 | I20: RB11 | J20: Kevin
A21: 16 | C21: Chris Olave | D21: WR | E21: NO | F21: 8 | G21: 4 out of 5 | H21: 4 out of 5 | I21: WR10 | J21: Marcelo
A22: 17 | B22: x | C22: Trey McBride | D22: TE | E22: ARI | F22: 14 | G22: 4 out of 5 | H22: 2 out of 5 | I22: TE1 | J22: Beto
A23: 18 | C23: George Pickens | D23: WR | E23: DAL | F23: 14 | G23: 4 out of 5 | H23: 4 out of 5 | I23: WR11 | J23: Steve
A24: 19 | B24: x | C24: Brock Bowers | D24: TE | E24: LV | F24: 13 | G24: 5 out of 5 | H24: 1 out of 5 | I24: TE2 | J24: Steve
A25: 20 | C25: De'Von Achane | D25: RB | E25: MIA | F25: 6 | G25: 4 out of 5 | H25: 4 out of 5 | I25: RB7 | J25: Emiliano
A26: 43 | B26: x | C26: Javonte Williams | D26: RB | E26: DAL | F26: 14 | G26: 4 out of 5 | H26: 4 out of 5 | I26: RB16 | J26: Kevin
A27: 23 | C27: Kenneth Walker III | D27: RB | E27: KC | F27: 5 | G27: 5 out of 5 | H27: 4 out of 5 | I27: RB9 | J27: Roy
A28: 24 | C28: Malik Nabers | D28: WR | E28: NYG | F28: 8 | G28: 4 out of 5 | H28: 4 out of 5 | I28: WR13 | J28: Marcelo
A29: 40 | B29: x | C29: Jeremiyah Love | D29: RB | E29: ARI | F29: 14 | G29: 5 out of 5 | H29: 4 out of 5 | I29: RB14 | J29: Marcelo
A30: 26 | B30: x | C30: Josh Allen | D30: QB | E30: BUF | F30: 7 | G30: 5 out of 5 | H30: 2 out of 5 | I30: QB1 | J30: Roy
A31: 39 | B31: x | C31: Breece Hall | D31: RB | E31: NYJ | F31: 13 | G31: 4 out of 5 | H31: 4 out of 5 | I31: RB13 | J31: Steve
A32: 27 | C32: Rashee Rice | D32: WR | E32: KC | F32: 5 | G32: 4 out of 5 | H32: 4 out of 5 | I32: WR14 | J32: Beto
A33: 29 | C33: Zay Flowers | D33: WR | E33: BAL | F33: 13 | G33: 4 out of 5 | H33: 2 out of 5 | I33: WR15 | J33: Roy
A34: 65 | B34: x | C34: Jadarian Price | D34: RB | E34: SEA | F34: 11 | G34: 4 out of 5 | H34: 4 out of 5 | I34: RB24 | J34: Kevin
A35: 30 | C35: Garrett Wilson | D35: WR | E35: NYJ | F35: 13 | G35: 4 out of 5 | H35: 4 out of 5 | I35: WR16 | J35: Roy
A36: 31 | C36: Lamar Jackson | D36: QB | E36: BAL | F36: 13 | G36: 4 out of 5 | H36: 4 out of 5 | I36: QB2 | J36: Steve
A37: 32 | C37: Ladd McConkey | D37: WR | E37: LAC | F37: 7 | G37: 4 out of 5 | H37: 3 out of 5 | I37: WR17 | J37: Emiliano
A38: 33 | C38: Jaylen Waddle | D38: WR | E38: DEN | F38: 10 | G38: 4 out of 5 | H38: 3 out of 5 | I38: WR18 | J38: Marcelo
A39: 34 | B39: x | C39: Derrick Henry | D39: RB | E39: BAL | F39: 13 | G39: 4 out of 5 | H39: 2 out of 5 | I39: RB12 | J39: Emiliano
A40: 35 | C40: Tee Higgins | D40: WR | E40: CIN | F40: 6 | G40: 5 out of 5 | H40: 2 out of 5 | I40: WR19 | J40: Steve
...
