Workbook

Sheet Teams
B1: Kevin | D1: Marcelo | F1: Emiliano | H1: Roy | J1: Beto | L1: Steve
A2: # | B2: Player | C2: POS | D2: Player | E2: POS | F2: Player | G2: POS | H2: Player | I2: POS | J2: Player | K2: POS | L2: Player | M2: POS
A3: 1 | B3: {=_xlfn._xlws.FILTER(ADPs!$D:$D,ADPs!$K:$K=Teams!B1)} -> Bijan Robinson | C3: {=_xlfn._xlws.FILTER(ADPs!$E:$E,ADPs!$K:$K=Teams!B1)} -> RB | D3: {=_xlfn._xlws.FILTER(ADPs!$D:$D,ADPs!$K:$K=Teams!D1)} -> Amon-Ra St. Brown | E3: {=_xlfn._xlws.FILTER(ADPs!$E:$E,ADPs!$K:$K=Teams!D1)} -> WR | F3: {=_xlfn._xlws.FILTER(ADPs!$D:$D,ADPs!$K:$K=Teams!F1)} -> Justin Jefferson | G3: {=_xlfn._xlws.FILTER(ADPs!$E:$E,ADPs!$K:$K=Teams!F1)} -> WR | H3: {=_xlfn._xlws.FILTER(ADPs!$D:$D,ADPs!$K:$K=Teams!H1)} -> Saquon Barkley | I3: {=_xlfn._xlws.FILTER(ADPs!$E:$E,ADPs!$K:$K=Teams!H1)} -> RB | J3: {=_xlfn._xlws.FILTER(ADPs!$D:$D,ADPs!$K:$K=Teams!J1)} -> Ja'Marr Chase | K3: {=_xlfn._xlws.FILTER(ADPs!$E:$E,ADPs!$K:$K=Teams!J1)} -> WR | L3: {=_xlfn._xlws.FILTER(ADPs!$D:$D,ADPs!$K:$K=Teams!L1)} -> CeeDee Lamb | M3: {=_xlfn._xlws.FILTER(ADPs!$E:$E,ADPs!$K:$K=Teams!L1)} -> WR
A4: 2 | B4: Nico Collins | C4: WR | D4: Jahmyr Gibbs | E4: RB | F4: Christian McCaffrey | G4: RB | H4: Brian Thomas Jr. | I4: WR | J4: Derrick Henry | K4: RB | L4: Puka Nacua | M4: WR
A5: 3 | B5: Bucky Irving | C5: RB | D5: Malik Nabers | E5: WR | F5: Chase Brown | G5: RB | H5: Ashton Jeanty | I5: RB | J5: Kyren Williams | K5: RB | L5: A.J. Brown | M5: WR
A6: 4 | B6: Josh Jacobs | C6: RB | D6: Ladd McConkey | E6: WR | F6: Trey McBride | G6: TE | H6: Garrett Wilson | I6: WR | J6: Omarion Hampton | K6: RB | L6: Calvin Ridley | M6: WR
A7: 5 | B7: Josh Allen | C7: QB | D7: Alvin Kamara | E7: RB | F7: Mike Evans | G7: WR | H7: Drake London | I7: WR | J7: Terry McLaurin | K7: WR | L7: Rashee Rice | M7: WR
A8: 6 | B8: Chuba Hubbard | C8: RB | D8: Patrick Mahomes II | E8: QB | F8: Jalen Hurts | G8: QB | H8: Jayden Daniels | I8: QB | J8: George Kittle | K8: TE | L8: David Montgomery | M8: RB
A9: 7 | B9: TreVeyon Henderson | C9: RB | D9: RJ Harvey | E9: RB | F9: Breece Hall | G9: RB | H9: Courtland Sutton | I9: WR | J9: De'Von Achane | K9: RB | L9: Sam LaPorta | M9: TE
A10: 8 | B10: Marvin Harrison Jr. | C10: WR | D10: Jerry Jeudy | E10: WR | F10: James Conner | G10: RB | H10: Tetairoa McMillan | I10: WR | J10: Joe Burrow | K10: QB | L10: Lamar Jackson | M10: QB
A11: 9 | B11: Ricky Pearsall | C11: WR | D11: Brock Bowers | E11: TE | F11: George Pickens | G11: WR | H11: Zay Flowers | I11: WR | J11: James Cook | K11: RB | L11: Jonathan Taylor | M11: RB
A12: 10 | B12: Emeka Egbuka | C12: WR | D12: Tyreek Hill | E12: WR | F12: Jameson Williams | G12: WR | H12: Deebo Samuel Sr. | I12: WR | J12: DK Metcalf | K12: WR | L12: Kenneth Walker III | M12: RB
A13: 11 | B13: Tyler Warren | C13: TE | D13: Xavier Worthy | E13: WR | F13: Isiah Pacheco | G13: RB | H13: Colston Loveland | I13: TE | J13: DeVonta Smith | K13: WR | L13: Jaylen Waddle | M13: WR
A14: 12 | B14: C.J. Stroud | C14: QB | D14: Tony Pollard | E14: RB | F14: Denver Broncos | G14: DS | H14: Jake Bates | I14: K3 | J14: Aaron Jones Sr. | K14: RB | L14: D'Andre Swift | M14: RB
A15: 13 | B15: Brandon Aubrey | C15: K1 | D15: Chris Olave | E15: WR | F15: Wil Lutz | G15: K4 | J15: DJ Moore | K15: WR | L15: Chris Boswell | M15: K7
A16: 14 | B16: Jaxon Smith-Njigba | C16: WR | J16: T.J. Hockenson | K16: TE
A17: 15 | B17: Green Bay Packers | C17: DS | J17: Matthew Golden | K17: WR
A18: 16
A19: 17
A20: 18
B22: QB | C22: =+COUNTIF(C$3:C$20, $B22) -> 2 | D22: QB | E22: =+COUNTIF(E$3:E$20, $B22) -> 1 | F22: QB | G22: =+COUNTIF(G$3:G$20, $B22) -> 1 | H22: QB | I22: =+COUNTIF(I$3:I$20, $B22) -> 1 | J22: QB | K22: =+COUNTIF(K$3:K$20, $B22) -> 1 | L22: QB | M22: =+COUNTIF(M$3:M$20, $B22) -> 1
B23: RB | C23: =+COUNTIF(C$3:C$20, $B23) -> 5 | D23: RB | E23: =+COUNTIF(E$3:E$20, $B23) -> 4 | F23: RB | G23: =+COUNTIF(G$3:G$20, $B23) -> 5 | H23: RB | I23: =+COUNTIF(I$3:I$20, $B23) -> 2 | J23: RB | K23: =+COUNTIF(K$3:K$20, $B23) -> 6 | L23: RB | M23: =+COUNTIF(M$3:M$20, $B23) -> 4
B24: WR | C24: =+COUNTIF(C$3:C$20, $B24) -> 5 | D24: WR | E24: =+COUNTIF(E$3:E$20, $B24) -> 7 | F24: WR | G24: =+COUNTIF(G$3:G$20, $B24) -> 4 | H24: WR | I24: =+COUNTIF(I$3:I$20, $B24) -> 7 | J24: WR | K24: =+COUNTIF(K$3:K$20, $B24) -> 6 | L24: WR | M24: =+COUNTIF(M$3:M$20, $B24) -> 6
B25: TE | C25: =+COUNTIF(C$3:C$20, $B25) -> 1 | D25: TE | E25: =+COUNTIF(E$3:E$20, $B25) -> 1 | F25: TE | G25: =+COUNTIF(G$3:G$20, $B25) -> 1 | H25: TE | I25: =+COUNTIF(I$3:I$20, $B25) -> 1 | J25: TE | K25: =+COUNTIF(K$3:K$20, $B25) -> 2 | L25: TE | M25: =+COUNTIF(M$3:M$20, $B25) -> 1
B26: DS | C26: =+COUNTIF(C$3:C$20, $B26) -> 1 | D26: DS | E26: =+COUNTIF(E$3:E$20, $B26) -> 0 | F26: DS | G26: =+COUNTIF(G$3:G$20, $B26) -> 1 | H26: DS | I26: =+COUNTIF(I$3:I$20, $B26) -> 0 | J26: DS | K26: =+COUNTIF(K$3:K$20, $B26) -> 0 | L26: DS | M26: =+COUNTIF(M$3:M$20, $B26) -> 0

Sheet ADPs
A1: Rank | B1: Interest | C1: NFL | D1: Player | E1: Pos | F1: Team | G1: Bye | H1: POS1 | I1: ECR VS. ADP | J1: Proj Rd | K1: Taken
A2: 1 | B2: Yes | C2: 2 | D2: Bijan Robinson | E2: RB | F2: ATL | G2: 5 | H2: RB1 | I2: 0 | J2: 1 | K2: Kevin
A3: 2 | B3: Yes | C3: 6 | D3: Saquon Barkley | E3: RB | F3: PHI | G3: 9 | H3: RB3 | I3: -3 | J3: 1 | K3: Roy
A4: 3 | B4: Yes | C4: 1 | D4: Ja'Marr Chase | E4: WR | F4: CIN | G4: 10 | H4: WR1 | I4: 0 | J4: 1 | K4: Beto
A5: 4 | B5: Yes | C5: 4 | D5: Justin Jefferson | E5: WR | F5: MIN | G5: 6 | H5: WR3 | I5: 0 | J5: 1 | K5: Emiliano
A6: 5 | B6: Yes | C6: 8 | D6: Amon-Ra St. Brown | E6: WR | F6: DET | G6: 8 | H6: WR5 | I6: 0 | J6: 2 | K6: Marcelo
A7: 6 | B7: Maybe | C7: 3 | D7: CeeDee Lamb | E7: WR | F7: DAL | G7: 10 | H7: WR2 | I7: 3 | J7: 1 | K7: Steve
A8: 7 | B8: Yes | C8: 9 | D8: Nico Collins | E8: WR | F8: HOU | G8: 6 | H8: WR6 | I8: 4 | J8: 2 | K8: Kevin
A9: 8 | B9: Maybe | C9: 5 | D9: Jahmyr Gibbs | E9: RB | F9: DET | G9: 8 | H9: RB2 | I9: 0 | J9: 1 | K9: Marcelo
A10: 9 | B10: Yes | C10: 21 | D10: Derrick Henry | E10: RB | F10: BAL | G10: 7 | H10: RB7 | I10: -11 | J10: 3 | K10: Beto
A11: 10 | B11: Maybe | C11: 11 | D11: Christian McCaffrey | E11: RB | F11: SF | G11: 14 | H11: RB4 | I11: -4 | J11: 1 | K11: Emiliano
A12: 11 | B12: Yes | C12: 10 | D12: Puka Nacua | E12: WR | F12: LAR | G12: 8 | H12: WR7 | I12: 1 | J12: 2 | K12: Steve
A13: 12 | B13: Maybe | C13: 7 | D13: Malik Nabers | E13: WR | F13: NYG | G13: 14 | H13: WR4 | I13: 2 | J13: 2 | K13: Marcelo
... A37: 36 | B37: Yes | C37: 83 | D37: Emeka Egbuka | E37: WR | F37: TB | G37: 9 | H37: WR39 | I37: 10 | J37: 9 | K37: Kevin
A38: 37 | B38: Yes | C38: 108 | D38: Tyler Warren | E38: TE | F38: IND | G38: 11 | H38: TE11 | I38: -17 | J38: 10+ | K38: Kevin
A39: 38 | B39: Yes | C39: 116 | D39: C.J. Stroud | E39: QB | F39: HOU | G39: 6 | H39: QB19 | I39: 9 | J39: 10+ | K39: Kevin
A40: 39 | B40: Yes | C40: 183 | D40: Brandon Aubrey | E40: K1 | F40: DAL | G40: 10 | H40: K1 | I40: -80 | J40: 10+ | K40: Kevin
A41: 40 | B41: Maybe | C41: 37 | D41: Jalen Hurts | E41: QB | F41: PHI | G41: 9 | H41: QB4 | I41: -3 | J41: 5 | K41: Emiliano
A42: 41 | B42: Maybe | C42: 39 | D42: Alvin Kamara | E42: RB | F42: NO | G42: 11 | H42: RB13 | I42: -2 | J42: 5 | K42: Marcelo
A43: 42 | B43: Maybe | C43: 42 | D43: James Cook | E43: RB | F43: BUF | G43: 7 | H43: RB15 | I43: -14 | J43: 5 | K43: Beto
A44: 43 | B44: Maybe | C44: 45 | D44: DK Metcalf | E44: WR | F44: PIT | G44: 5 | H44: WR22 | I44: 4 | J44: 5 | K44: Beto
A45: 44 | B45: Maybe | C45: 46 | D45: Breece Hall | E45: RB | F45: NYJ | G45: 9 | H45: RB17 | I45: -11 | J45: 5 | K45: Emiliano
A46: 45 | B46: Maybe | C46: 48 | D46: DeVonta Smith | E46: WR | F46: PHI | G46: 9 | H46: WR23 | I46: 6 | J46: 6 | K46: Beto
A47: 46 | B47: Maybe | C47: 55 | D47: Calvin Ridley | E47: WR | F47: TEN | G47: 10 | H47: WR27 | I47: 11 | J47: 6 | K47: Steve
A48: 47 | B48: Maybe | C48: 51 | D48: James Conner | E48: RB | F48: ARI | G48: 8 | H48: RB19 | I48: -5 | J48: 6 | K48: Emiliano
A49: 48 | B49: Maybe | C49: 68 | D49: Rashee Rice | E49: WR | F49: KC | G49: 10 | H49: WR32 | I49: -11 | J49: 7 | K49: Steve
A50: 49 | B50: Maybe | C50: 77 | D50: Jakobi Meyers | E50: WR | F50: LV | G50: 8 | H50: WR37 | I50: 7 | J50: 8
A51: 50 | B51: Maybe | C51: 62 | D51: Patrick Mahomes II | E51: QB | F51: KC | G51: 10 | H51: QB6 | I51: -12 | J51: 7 | K51: Marcelo
A52: 51 | B52: Maybe | C52: 73 | D52: Bo Nix | E52: QB | F52: DEN | G52: 12 | H52: QB8 | I52: -2 | J52: 8
A53: 52 | B53: Maybe | C53: 61 | D53: RJ Harvey | E53: RB | F53: DEN | G53: 12 | H53: RB23 | I53: -1 | J53: 7 | K53: Marcelo
A54: 53 | B54: Maybe | C54: 102 | D54: Cooper Kupp | E54: WR | F54: SEA | G54: 8 | H54: WR46 | I54: -15 | J54: 10+
A55: 54 | B55: Maybe | C55: 76 | D55: Stefon Diggs | E55: WR | F55: NE | G55: 14 | H55: WR36 | I55: 6 | J55: 8
A56: 55 | B56: Maybe | C56: 65 | D56: David Montgomery | E56: RB | F56: DET | G56: 8 | H56: RB24 | I56: -9 | J56: 7 | K56: Steve
A57: 56 | B57: Maybe | C57: 66 | D57: Aaron Jones Sr. | E57: RB | F57: MIN | G57: 6 | H57: RB25 | I57: 2 | J57: 7 | K57: Beto
A58: 57 | B58: Maybe | C58: 70 | D58: Jerry Jeudy | E58: WR | F58: CLE | G58: 9 | H58: WR34 | I58: 4 | J58: 8 | K58: Marcelo
A59: 58 | B59: Maybe | C59: 72 | D59: Sam LaPorta | E59: TE | F59: DET | G59: 8 | H59: TE5 | I59: -20 | J59: 8 | K59: Steve
A60: 59 | B60: Yes | C60: 96 | D60: Zach Charbonnet | E60: RB | F60: SEA | G60: 8 | H60: RB31 | I60: 18 | J60: 10+
A61: 60 | B61: Maybe | C61: 75 | D61: Travis Kelce | E61: TE | F61: KC | G61: 10 | H61: TE6 | I61: -13 | J61: 8
A62: 61 | B62: Maybe | C62: 111 | D62: Jordan Love | E62: QB | F62: GB | G62: 5 | H62: QB17 | I62: 24 | J62: 10+
A63: 62 | B63: Maybe | C63: 80 | D63: Kyler Murray | E63: QB | F63: ARI | G63: 8 | H63: QB9 | I63: 5 | J63: 8
...

Sheet QB
A1: rank | B1: player | C1: Interest | D1: cmp | E1: att | F1: pct | G1: yds | H1: y/a | I1: td | J1: int | K1: sacks | L1: att | M1: yds | N1: td | O1: fl | P1: g | Q1: fpts | R1: fpts/g | S1: pos | T1: team
A2: 1 | B2: Josh Allen | C2: Yes | D2: 385 | E2: 579 | F2: 66.5 | G2: 4306 | H2: 7.4 | I2: 29 | J2: 18 | K2: 24 | L2: 111 | M2: 524 | N2: 15 | O2: 4 | P2: 17 | Q2: 410.9 | R2: 24.2 | S2: QB | T2: BUF
A3: 2 | B3: Jalen Hurts | D3: 352 | E3: 538 | F3: 65.4 | G3: 3858 | H3: 7.2 | I3: 23 | J3: 15 | K3: 36 | L3: 157 | M3: 605 | N3: 15 | O3: 5 | P3: 17 | Q3: 371.9 | R3: 21.9 | S3: QB | T3: PHI
A4: 3 | B4: Dak Prescott | D4: 410 | E4: 590 | F4: 69.5 | G4: 4516 | H4: 7.7 | I4: 36 | J4: 9 | K4: 39 | L4: 55 | M4: 242 | N4: 2 | O4: 2 | P4: 17 | Q4: 352 | R4: 20.7 | S4: QB | T4: DAL
A5: 4 | B5: Lamar Jackson | D5: 307 | E5: 457 | F5: 67.2 | G5: 3678 | H5: 8 | I5: 24 | J5: 7 | K5: 37 | L5: 148 | M5: 821 | N5: 5 | O5: 6 | P5: 16 | Q5: 338.2 | R5: 21.1 | S5: QB | T5: BAL
A6: 5 | B6: Jordan Love | C6: Yes | D6: 372 | E6: 579 | F6: 64.2 | G6: 4159 | H6: 7.2 | I6: 32 | J6: 11 | K6: 30 | L6: 50 | M6: 247 | N6: 4 | O6: 3 | P6: 17 | Q6: 330.1 | R6: 19.4 | S6: QB | T6: GB
A7: 6 | B7: Brock Purdy | D7: 308 | E7: 444 | F7: 69.4 | G7: 4280 | H7: 9.6 | I7: 31 | J7: 11 | K7: 28 | L7: 39 | M7: 144 | N7: 2 | O7: 2 | P7: 16 | Q7: 306.6 | R7: 19.2 | S7: QB | T7: SF
A8: 7 | B8: Jared Goff | C8: Yes | D8: 407 | E8: 605 | F8: 67.3 | G8: 4575 | H8: 7.6 | I8: 30 | J8: 12 | K8: 30 | L8: 32 | M8: 21 | N8: 2 | O8: 3 | P8: 17 | Q8: 302.9 | R8: 17.8 | S8: QB | T8: DET
A9: 8 | B9: Patrick Mahomes II | C9: Yes | D9: 401 | E9: 597 | F9: 67.2 | G9: 4183 | H9: 7 | I9: 27 | J9: 14 | K9: 27 | L9: 75 | M9: 389 | N9: 0 | O9: 3 | P9: 16 | Q9: 294.1 | R9: 18.4 | S9: QB | T9: KC
A10: 9 | B10: Tua Tagovailoa | D10: 388 | E10: 560 | F10: 69.3 | G10: 4624 | H10: 8.3 | I10: 29 | J10: 14 | K10: 29 | L10: 35 | M10: 74 | N10: 0 | O10: 5 | P10: 17 | Q10: 284.4 | R10: 16.7 | S10: QB | T10: MIA
A11: 10 | B11: Baker Mayfield | D11: 364 | E11: 566 | F11: 64.3 | G11: 4044 | H11: 7.1 | I11: 28 | J11: 10 | K11: 40 | L11: 62 | M11: 163 | N11: 1 | O11: 3 | P11: 17 | Q11: 284 | R11: 16.7 | S11: QB | T11: TB
A12: 11 | B12: C.J. Stroud | D12: 319 | E12: 499 | F12: 63.9 | G12: 4108 | H12: 8.2 | I12: 23 | J12: 5 | K12: 38 | L12: 39 | M12: 167 | N12: 3 | O12: 4 | P12: 15 | Q12: 281.1 | R12: 18.7 | S12: QB | T12: HOU
A13: 12 | B13: Sam Howell | D13: 388 | E13: 612 | F13: 63.4 | G13: 3946 | H13: 6.4 | I13: 21 | J13: 21 | K13: 65 | L13: 48 | M13: 263 | N13: 5 | O13: 2 | P13: 17 | Q13: 278.6 | R13: 16.4 | S13: QB | T13: SEA
A14: 13 | B14: Trevor Lawrence | D14: 370 | E14: 564 | F14: 65.6 | G14: 4016 | H14: 7.1 | I14: 21 | J14: 14 | K14: 35 | L14: 70 | M14: 339 | N14: 4 | O14: 7 | P14: 16 | Q14: 276.6 | R14: 17.3 | S14: QB | T14: JAC
A15: 14 | B15: Russell Wilson | D15: 297 | E15: 447 | F15: 66.4 | G15: 3070 | H15: 6.9 | I15: 26 | J15: 8 | K15: 45 | L15: 80 | M15: 341 | N15: 3 | O15: 5 | P15: 15 | Q15: 264.9 | R15: 17.7 | S15: QB | T15: PIT
A16: 15 | B16: Matthew Stafford | D16: 326 | E16: 521 | F16: 62.6 | G16: 3965 | H16: 7.6 | I16: 24 | J16: 11 | K16: 30 | L16: 21 | M16: 65 | N16: 0 | O16: 0 | P16: 15 | Q16: 254.3 | R16: 17 | S16: QB | T16: LAR
A17: 16 | B17: Derek Carr | D17: 375 | E17: 548 | F17: 68.4 | G17: 3878 | H17: 7.1 | I17: 25 | J17: 8 | K17: 31 | L17: 32 | M17: 40 | N17: 0 | O17: 3 | P17: 17 | Q17: 249.1 | R17: 14.7 | S17: QB | T17: NO
A18: 17 | B18: Justin Herbert | D18: 297 | E18: 456 | F18: 65.1 | G18: 3134 | H18: 6.9 | I18: 20 | J18: 7 | K18: 29 | L18: 52 | M18: 228 | N18: 3 | O18: 1 | P18: 13 | Q18: 241.2 | R18: 18.6 | S18: QB | T18: LAC
A19: 18 | B19: Justin Fields | D19: 227 | E19: 370 | F19: 61.4 | G19: 2562 | H19: 6.9 | I19: 16 | J19: 9 | K19: 44 | L19: 124 | M19: 657 | N19: 4 | O19: 4 | P19: 13 | Q19: 239.1 | R19: 18.4 | S19: QB | T19: PIT
A20: 19 | B20: Geno Smith | D20: 323 | E20: 499 | F20: 64.7 | G20: 3624 | H20: 7.3 | I20: 20 | J20: 9 | K20: 31 | L20: 37 | M20: 155 | N20: 1 | O20: 3 | P20: 15 | Q20: 236.4 | R20: 15.8 | S20: QB | T20: SEA
A21: 20 | B21: Joshua Dobbs | D21: 262 | E21: 417 | F21: 62.8 | G21: 2464 | H21: 5.9 | I21: 13 | J21: 10 | K21: 30 | L21: 77 | M21: 421 | N21: 6 | O21: 7 | P21: 13 | Q21: 210.5 | R21: 16.2 | S21: QB | T21: SF
... A127: 126 | B127: Kyle Allen | D127: 0 | E127: 0 | F127: 0 | G127: 0 | H127: 0 | I127: 0 | J127: 0 | K127: 0 | L127: 13 | M127: -13 | N127: 0 | O127: 0 | P127: 7 | Q127: -1.3 | R127: -0.2 | S127: QB | T127: PIT

Sheet RB
A1: rank | B1: player | C1: team | D1: DB1 | E1: att | F1: yds | G1: 20+ | H1: td | I1: rec | J1: tgt | K1: fl | L1: g | M1: fpts | N1: avg_snap_pct_played | O1: avg_snap_pct_global | P1: rb_targets | Q1: rb_pct | R1: total_targets | S1: att/g | T1: score | U1: yds/att | V1: tgt/g | W1: rec/g | X1: td/g
A2: 8 | B2: Derrick Henry | C2: BAL | D2: x | E2: 280 | F2: 1167 | G2: 5 | H2: 12 | I2: 28 | J2: 36 | K2: 0 | L2: 17 | M2: 246.7 | N2: 53.588235 | O2: 53.588235 | P2: 79 | Q2: 16.6 | R2: 476 | S2: 16.470588 | T2: 5 | U2: 4.1678571 | V2: 2.1176471 | W2: 1.6470588 | X2: 0.70588235
A3: 1 | B3: Christian McCaffrey | C3: SF | E3: 272 | F3: 1459 | G3: 9 | H3: 14 | I3: 67 | J3: 83 | K3: 2 | L3: 16 | M3: 391.3 | N3: 81.6875 | O3: 76.882353 | P3: 112 | Q3: 23.8 | R3: 471 | S3: 17 | T3: 10 | U3: 5.3639706 | V3: 5.1875 | W3: 4.1875 | X3: 0.875
A4: 4 | B4: Rachaad White | C4: TB | D4: x | E4: 272 | F4: 990 | G4: 3 | H4: 6 | I4: 64 | J4: 70 | K4: 2 | L4: 17 | M4: 267.9 | N4: 78.411765 | O4: 78.411765 | P4: 94 | Q4: 17.1 | R4: 550 | S4: 16 | T4: 10 | U4: 3.6397059 | V4: 4.1176471 | W4: 3.7647059 | X4: 0.35294118
A5: 3 | B5: Travis Etienne Jr. | C5: JAC | D5: x | E5: 267 | F5: 1008 | G5: 6 | H5: 11 | I5: 58 | J5: 73 | K5: 0 | L5: 17 | M5: 282.4 | N5: 73.352941 | O5: 73.352941 | P5: 91 | Q5: 15 | R5: 607 | S5: 15.705882 | T5: 9.5 | U5: 3.7752809 | V5: 4.2941176 | W5: 3.4117647 | X5: 0.64705882
A6: 6 | B6: Joe Mixon | C6: HOU | E6: 257 | F6: 1034 | G6: 3 | H6: 9 | I6: 52 | J6: 64 | K6: 0 | L6: 17 | M6: 267 | N6: 68.882353 | O6: 68.882353 | P6: 71 | Q6: 12.6 | R6: 565 | S6: 15.117647 | T6: 9 | U6: 4.0233463 | V6: 3.7647059 | W6: 3.0588235 | X6: 0.52941176
A7: 23 | B7: Najee Harris | C7: PIT | E7: 255 | F7: 1035 | G7: 8 | H7: 8 | I7: 29 | J7: 38 | K7: 1 | L7: 17 | M7: 195.5 | N7: 53 | O7: 53 | P7: 114 | Q7: 23.6 | R7: 484 | S7: 15 | T7: 5.5 | U7: 4.0588235 | V7: 2.2352941 | W7: 1.7058824 | X7: 0.47058824
A8: 14 | B8: Tony Pollard | C8: TEN | E8: 252 | F8: 1005 | G8: 6 | H8: 6 | I8: 55 | J8: 67 | K8: 1 | L8: 17 | M8: 222.6 | N8: 70.529412 | O8: 70.529412 | P8: 106 | Q8: 22.3 | R8: 476 | S8: 14.823529 | T8: 9 | U8: 3.9880952 | V8: 3.9411765 | W8: 3.2352941 | X8: 0.35294118
A9: 13 | B9: Saquon Barkley | C9: PHI | D9: x | E9: 247 | F9: 962 | G9: 7 | H9: 6 | I9: 41 | J9: 60 | K9: 2 | L9: 14 | M9: 223.2 | N9: 78.857143 | O9: 64.941176 | P9: 93 | Q9: 17.7 | R9: 525 | S9: 17.642857 | T9: 8 | U9: 3.8947368 | V9: 4.2857143 | W9: 2.9285714 | X9: 0.42857143
A10: 27 | B10: Chuba Hubbard | C10: CAR | E10: 238 | F10: 902 | G10: 4 | H10: 5 | I10: 39 | J10: 44 | K10: 0 | L10: 17 | M10: 182.5 | N10: 59.529412 | O10: 59.529412 | P10: 92 | Q10: 17.2 | R10: 534 | S10: 14 | T10: 7 | U10: 3.789916 | V10: 2.5882353 | W10: 2.2941176 | X10: 0.29411765
A11: 12 | B11: James Cook | C11: BUF | E11: 237 | F11: 1122 | G11: 6 | H11: 2 | I11: 44 | J11: 54 | K11: 2 | L11: 17 | M11: 232.7 | N11: 54.823529 | O11: 54.823529 | P11: 86 | Q11: 15.8 | R11: 545 | S11: 13.941176 | T11: 7.5 | U11: 4.7341772 | V11: 3.1764706 | W11: 2.5882353 | X11: 0.11764706
A12: 28 | B12: Josh Jacobs | C12: GB | D12: x | E12: 233 | F12: 805 | G12: 3 | H12: 6 | I12: 37 | J12: 54 | K12: 1 | L12: 13 | M12: 181.1 | N12: 76.076923 | O12: 58.176471 | P12: 94 | Q12: 16.8 | R12: 561 | S12: 17.923077 | T12: 8 | U12: 3.4549356 | V12: 4.1538462 | W12: 2.8461538 | X12: 0.46153846
A13: 20 | B13: D'Andre Swift | C13: CHI | E13: 229 | F13: 1049 | G13: 6 | H13: 5 | I13: 39 | J13: 49 | K13: 1 | L13: 16 | M13: 199.3 | N13: 57.9375 | O13: 54.529412 | P13: 106 | Q13: 22.2 | R13: 477 | S13: 14.3125 | T13: 7 | U13: 4.580786 | V13: 3.0625 | W13: 2.4375 | X13: 0.3125
A14: 7 | B14: Kyren Williams | C14: LAR | D14: x | E14: 228 | F14: 1144 | G14: 7 | H14: 12 | I14: 32 | J14: 48 | K14: 2 | L14: 12 | M14: 255 | N14: 82.75 | O14: 58.411765 | P14: 69 | Q14: 12.4 | R14: 555 | S14: 19 | T14: 7.5 | U14: 5.0175439 | V14: 4 | W14: 2.6666667 | X14: 1
A15: 2 | B15: Breece Hall | C15: NYJ | D15: x | E15: 223 | F15: 994 | G15: 7 | H15: 5 | I15: 76 | J15: 95 | K15: 0 | L15: 17 | M15: 290.5 | N15: 59.176471 | O15: 59.176471 | P15: 149 | Q15: 26.5 | R15: 562 | S15: 13.117647 | T15: 10 | U15: 4.4573991 | V15: 5.5882353 | W15: 4.4705882 | X15: 0.29411765
A16: 17 | B16: David Montgomery | C16: DET | E16: 219 | F16: 1015 | G16: 4 | H16: 13 | I16: 16 | J16: 24 | K16: 1 | L16: 14 | M16: 207.2 | N16: 48.357143 | O16: 39.823529 | P16: 102 | Q16: 17.9 | R16: 571 | S16: 15.642857 | T16: 3.5 | U16: 4.6347032 | V16: 1.7142857 | W16: 1.1428571 | X16: 0.92857143
A17: 19 | B17: Kenneth Walker III | C17: SEA | E17: 219 | F17: 905 | G17: 7 | H17: 8 | I17: 29 | J17: 37 | K17: 0 | L17: 15 | M17: 199.4 | N17: 54.2 | O17: 47.823529 | P17: 86 | Q17: 15.8 | R17: 546 | S17: 14.6 | T17: 6.5 | U17: 4.1324201 | V17: 2.4666667 | W17: 1.9333333 | X17: 0.53333333
A18: 29 | B18: Javonte Williams | C18: DEN | E18: 217 | F18: 774 | G18: 2 | H18: 3 | I18: 47 | J18: 58 | K18: 1 | L18: 16 | M18: 179.2 | N18: 48.0625 | O18: 45.235294 | P18: 153 | Q18: 32.1 | R18: 477 | S18: 13.5625 | T18: 8 | U18: 3.5668203 | V18: 3.625 | W18: 2.9375 | X18: 0.1875
A19: 32 | B19: Devin Singletary | C19: NYG | E19: 216 | F19: 898 | G19: 3 | H19: 4 | I19: 30 | J19: 38 | K19: 0 | L19: 17 | M19: 167.3 | N19: 55.823529 | O19: 55.823529 | P19: 98 | Q19: 20.2 | R19: 484 | S19: 12.705882 | T19: 5.5 | U19: 4.1574074 | V19: 2.2352941 | W19: 1.7647059 | X19: 0.23529412
A20: 9 | B20: Bijan Robinson | C20: ATL | D20: x | E20: 214 | F20: 976 | G20: 7 | H20: 4 | I20: 58 | J20: 86 | K20: 3 | L20: 17 | M20: 246.3 | N20: 68 | O20: 68 | P20: 124 | Q20: 24.5 | R20: 507 | S20: 12.588235 | T20: 9.5 | U20: 4.5607477 | V20: 5.0588235 | W20: 3.4117647 | X20: 0.23529412
A21: 5 | B21: Raheem Mostert | C21: MIA | E21: 209 | F21: 1012 | G21: 7 | H21: 18 | I21: 25 | J21: 32 | K21: 1 | L21: 15 | M21: 267.7 | N21: 56.6 | O21: 49.941176 | P21: 125 | Q21: 22.8 | R21: 549 | S21: 13.933333 | T21: 5 | U21: 4.8421053 | V21: 2.1333333 | W21: 1.6666667 | X21: 1.2
A22: 18 | B22: James Conner | C22: ARI | E22: 208 | F22: 1040 | G22: 11 | H22: 7 | I22: 27 | J22: 33 | K22: 0 | L22: 13 | M22: 201.5 | N22: 61.615385 | O22: 47.117647 | P22: 84 | Q22: 15.6 | R22: 540 | S22: 16 | T22: 6.5 | U22: 5 | V22: 2.5384615 | W22: 2.0769231 | X22: 0.53846154
A23: 15 | B23: Isiah Pacheco | C23: KC | E23: 205 | F23: 935 | G23: 6 | H23: 7 | I23: 44 | J23: 49 | K23: 1 | L23: 14 | M23: 213.9 | N23: 61.214286 | O23: 50.411765 | P23: 108 | Q23: 18.1 | R23: 598 | S23: 14.642857 | T23: 9 | U23: 4.5609756 | V23: 3.5 | W23: 3.1428571 | X23: 0.5
A24: 16 | B24: Jerome Ford | C24: CLE | E24: 204 | F24: 813 | G24: 5 | H24: 4 | I24: 44 | J24: 63 | K24: 1 | L24: 17 | M24: 211.2 | N24: 50.529412 | O24: 50.529412 | P24: 96 | Q24: 16.1 | R24: 597 | S24: 12 | T24: 7.5 | U24: 3.9852941 | V24: 3.7058824 | W24: 2.5882353 | X24: 0.23529412
A25: 25 | B25: Gus Edwards | C25: LAC | E25: 198 | F25: 810 | G25: 6 | H25: 13 | I25: 12 | J25: 13 | K25: 2 | L25: 17 | M25: 187 | N25: 42.294118 | O25: 42.294118 | P25: 94 | Q25: 15.3 | R25: 613 | S25: 11.647059 | T25: 2 | U25: 4.0909091 | V25: 0.76470588 | W25: 0.70588235 | X25: 0.76470588
A26: 36 | B26: Tyler Allgeier | C26: ATL | E26: 186 | F26: 683 | G26: 2 | H26: 4 | I26: 18 | J26: 23 | K26: 0 | L26: 17 | M26: 137.6 | N26: 32.235294 | O26: 32.235294 | P26: 124 | Q26: 24.5 | R26: 507 | S26: 10.941176 | T26: 3 | U26: 3.672043 | V26: 1.3529412 | W26: 1.0588235 | X26: 0.23529412
A27: 30 | B27: Ezekiel Elliott | C27: DAL | E27: 184 | F27: 642 | G27: 0 | H27: 3 | I27: 51 | J27: 65 | K27: 1 | L27: 17 | M27: 174.5 | N27: 53.058824 | O27: 53.058824 | P27: 100 | Q27: 16.5 | R27: 605 | S27: 10.823529 | T27: 8.5 | U27: 3.4891304 | V27: 3.8235294 | W27: 3 | X27: 0.17647059
A28: 31 | B28: Zack Moss | C28: CIN | E28: 183 | F28: 794 | G28: 6 | H28: 5 | I28: 27 | J28: 37 | K28: 0 | L28: 14 | M28: 169.6 | N28: 55.5 | O28: 45.705882 | P28: 89 | Q28: 15.1 | R28: 591 | S28: 13.071429 | T28: 6 | U28: 4.3387978 | V28: 2.6428571 | W28: 1.9285714 | X28: 0.35714286
A29: 10 | B29: Jahmyr Gibbs | C29: DET | D29: x | E29: 182 | F29: 945 | G29: 10 | H29: 10 | I29: 52 | J29: 71 | K29: 1 | L29: 15 | M29: 242.1 | N29: 56.066667 | O29: 49.470588 | P29: 102 | Q29: 17.9 | R29: 571 | S29: 12.133333 | T29: 9.5 | U29: 5.1923077 | V29: 4.7333333 | W29: 3.4666667 | X29: 0.66666667
A30: 11 | B30: Alvin Kamara | C30: NO | E30: 180 | F30: 694 | G30: 0 | H30: 5 | I30: 75 | J30: 86 | K30: 0 | L30: 13 | M30: 233 | N30: 62.076923 | O30: 47.470588 | P30: 128 | Q30: 22.1 | R30: 579 | S30: 13.846154 | T30: 10 | U30: 3.8555556 | V30: 6.6153846 | W30: 5.7692308 | X30: 0.38461538
A31: 38 | B31: Alexander Mattison | C31: LV | E31: 180 | F31: 700 | G31: 1 | H31: 0 | I31: 30 | J31: 44 | K31: 2 | L31: 16 | M31: 133.2 | N31: 54.8125 | O31: 51.588235 | P31: 99 | Q31: 18.6 | R31: 531 | S31: 11.25 | T31: 6 | U31: 3.8888889 | V31: 2.75 | W31: 1.875 | X31: 0
A32: 26 | B32: Austin Ekeler | C32: WAS | E32: 179 | F32: 628 | G32: 3 | H32: 5 | I32: 51 | J32: 74 | K32: 4 | L32: 14 | M32: 185.4 | N32: 65.5 | O32: 53.941176 | P32: 108 | Q32: 18 | R32: 600 | S32: 12.785714 | T32: 10 | U32: 3.5083799 | V32: 5.2857143 | W32: 3.6428571 | X32: 0.35714286
A33: 21 | B33: Brian Robinson Jr. | C33: WAS | E33: 178 | F33: 733 | G33: 4 | H33: 5 | I33: 36 | J33: 43 | K33: 2 | L33: 15 | M33: 198.1 | N33: 49.4 | O33: 43.588235 | P33: 108 | Q33: 18 | R33: 600 | S33: 11.866667 | T33: 7 | U33: 4.1179775 | V33: 2.8666667 | W33: 2.4 | X33: 0.33333333
A34: 42 | B34: AJ Dillon | C34: GB | E34: 178 | F34: 613 | G34: 1 | H34: 2 | I34: 22 | J34: 28 | K34: 0 | L34: 15 | M34: 117.6 | N34: 51.266667 | O34: 45.235294 | P34: 94 | Q34: 16.8 | R34: 561 | S34: 11.866667 | T34: 4.5 | U34: 3.4438202 | V34: 1.8666667 | W34: 1.4666667 | X34: 0.13333333
A35: 33 | B35: Jonathan Taylor | C35: IND | E35: 169 | F35: 741 | G35: 4 | H35: 7 | I35: 19 | J35: 23 | K35: 0 | L35: 10 | M35: 156.4 | N35: 58.6 | O35: 34.470588 | P35: 83 | Q35: 15.2 | R35: 546 | S35: 16.9 | T35: 6 | U35: 4.3846154 | V35: 2.3 | W35: 1.9 | X35: 0.7
A36: 35 | B36: Rhamondre Stevenson | C36: NE | E36: 156 | F36: 619 | G36: 1 | H36: 4 | I36: 38 | J36: 51 | K36: 1 | L36: 12 | M36: 145.7 | N36: 62.25 | O36: 43.941176 | P36: 131 | Q36: 24.2 | R36: 541 | S36: 13 | T36: 9 | U36: 3.9679487 | V36: 4.25 | W36: 3.1666667 | X36: 0.33333333
A37: 22 | B37: Jaylen Warren | C37: PIT | E37: 149 | F37: 784 | G37: 6 | H37: 4 | I37: 61 | J37: 74 | K37: 2 | L37: 17 | M37: 196.4 | N37: 48.529412 | O37: 48.529412 | P37: 114 | Q37: 23.6 | R37: 484 | S37: 8.7647059 | T37: 9.5 | U37: 5.261745 | V37: 4.3529412 | W37: 3.5882353 | X37: 0.23529412
A38: 55 | B38: Dameon Pierce | C38: HOU | E38: 145 | F38: 416 | G38: 1 | H38: 2 | I38: 13 | J38: 17 | K38: 0 | L38: 14 | M38: 82.7 | N38: 34.615385 | O38: 26.470588 | P38: 71 | Q38: 12.6 | R38: 565 | S38: 10.357143 | T38: 2 | U38: 2.8689655 | V38: 1.2142857 | W38: 0.92857143 | X38: 0.14285714
A39: 37 | B39: Aaron Jones | C39: MIN | E39: 142 | F39: 656 | G39: 3 | H39: 2 | I39: 30 | J39: 43 | K39: 1 | L39: 11 | M39: 134.9 | N39: 49.272727 | O39: 31.882353 | P39: 90 | Q39: 14.9 | R39: 606 | S39: 12.909091 | T39: 8 | U39: 4.6197183 | V39: 3.9090909 | W39: 2.7272727 | X39: 0.18181818
A40: 41 | B40: Kareem Hunt | C40: FA | E40: 135 | F40: 411 | G40: 0 | H40: 9 | I40: 15 | J40: 21 | K40: 0 | L40: 15 | M40: 118.5 | N40: 31.066667 | O40: 27.411765 | S40: 9 | T40: 2.5 | U40: 3.0444444 | V40: 1.4 | W40: 1 | X40: 0.6
...

Sheet WR
A1: rank | B1: player | C1: team | D1: rec | E1: tgt | F1: yds | G1: 20+ | H1: td | I1: att | J1: fl | K1: g | L1: fpts | M1: rank_1 | N1: rec_1 | O1: tgt_1 | P1: yds_1 | Q1: 20+_1 | R1: td_1 | S1: att_1 | T1: fl_1 | U1: g_1 | V1: fpts_1 | W1: rank_2 | X1: rec_2 | Y1: tgt_2 | Z1: yds_2 | AA1: 20+_2 | AB1: td_2 | AC1: att_2 | AD1: fl_2 | AE1: g_2 | AF1: fpts_2 | AG1: team_0 | AH1: avg_snap_pct_played | AI1: avg_snap_pct_global | AJ1: team_1 | AK1: avg_snap_pct_played_1 | AL1: avg_snap_pct_global_1 | AM1: team_2 | AN1: avg_snap_pct_played_2 | AO1: avg_snap_pct_global_2 | AP1: wr_targets | AQ1: wr_pct | AR1: total_targets | AS1: wr_targets_1 | AT1: wr_pct_1 | AU1: total_targets_1 | AV1: wr_targets_2 | AW1: wr_pct_2 | AX1: total_targets_2 | AY1: tgt_teammates | AZ1: tgt_teammates_1 | BA1: tgt_teammates_2
A2: 4 | B2: Puka Nacua | C2: LAR | D2: 105 | E2: 160 | F2: 1486 | G2: 25 | H2: 6 | I2: 12 | J2: 0 | K2: 17 | L2: 298.5 | AG2: LAR | AH2: 87.176471 | AI2: 87.176471 | AP2: 398 | AQ2: 71.7 | AR2: 555 | AY2: 223 | AZ2: 0 | BA2: 0
A3: 40 | B3: Cooper Kupp | C3: LAR | D3: 59 | E3: 95 | F3: 737 | G3: 10 | H3: 5 | I3: 1 | J3: 0 | K3: 12 | L3: 164.4 | M3: 23 | N3: 75 | O3: 98 | P3: 812 | Q3: 11 | R3: 6 | S3: 9 | T3: 1 | U3: 9 | V3: 201.4 | W3: 1 | X3: 145 | Y3: 191 | Z3: 1947 | AA3: 30 | AB3: 16 | AC3: 4 | AD3: 0 | AE3: 17 | AF3: 439.5 | AG3: LAR | AH3: 90.583333 | AI3: 63.941176 | AJ3: LAR | AK3: 95 | AL3: 50.294118 | AM3: LAR | AN3: 94.117647 | AO3: 94.117647 | AP3: 398 | AQ3: 71.7 | AR3: 555 | AS3: 331 | AT3: 64.1 | AU3: 516 | AV3: 432 | AW3: 71.8 | AX3: 602 | AY3: 288 | AZ3: 228 | BA3: 178
A4: 62 | B4: Tutu Atwell | C4: LAR | D4: 39 | E4: 67 | F4: 483 | G4: 8 | H4: 3 | I4: 5 | J4: 0 | K4: 16 | L4: 112.4 | M4: 101 | N4: 18 | O4: 35 | P4: 298 | Q4: 5 | R4: 1 | S4: 9 | T4: 0 | U4: 12 | V4: 63.2 | W4: 237 | X4: 0 | Y4: 0 | Z4: 0 | AA4: 0 | AB4: 0 | AC4: 0 | AD4: 0 | AE4: 6 | AF4: 0 | AG4: LAR | AH4: 64.5625 | AI4: 60.764706 | AJ4: LAR | AK4: 44.5 | AL4: 31.411765 | AM4: LAR | AN4: 11 | AO4: 0.64705882 | AP4: 398 | AQ4: 71.7 | AR4: 555 | AS4: 331 | AT4: 64.1 | AU4: 516 | AV4: 432 | AW4: 71.8 | AX4: 602 | AY4: 316 | AZ4: 291 | BA4: 369
A5: 79 | B5: Demarcus Robinson | C5: LAR | D5: 26 | E5: 39 | F5: 371 | G5: 7 | H5: 4 | I5: 1 | J5: 1 | K5: 13 | L5: 87.4 | M5: 69 | N5: 48 | O5: 75 | P5: 458 | Q5: 4 | R5: 2 | S5: 0 | T5: 1 | U5: 16 | V5: 103.8 | W5: 104 | X5: 25 | Y5: 41 | Z5: 264 | AA5: 3 | AB5: 3 | AC5: 0 | AD5: 0 | AE5: 15 | AF5: 69.4 | AG5: LAR | AH5: 44.076923 | AI5: 33.705882 | AJ5: BAL | AK5: 59.75 | AL5: 56.235294 | AM5: KC | AN5: 58.266667 | AO5: 51.411765 | AP5: 398 | AQ5: 71.7 | AR5: 555 | AS5: 198 | AT5: 42.6 | AU5: 465 | AV5: 362 | AW5: 56.9 | AX5: 636 | AY5: 344 | AZ5: 101 | BA5: 302
A6: 178 | B6: Tyler Johnson | C6: LAR | D6: 2 | E6: 3 | F6: 8 | G6: 0 | H6: 1 | I6: 0 | J6: 0 | K6: 1 | L6: 8.8 | W6: 101 | X6: 36 | Y6: 55 | Z6: 360 | AA6: 4 | AB6: 0 | AC6: 0 | AD6: 0 | AE6: 16 | AF6: 72 | AG6: LAR | AH6: 54 | AI6: 3.1764706 | AM6: TB | AN6: 54.4375 | AO6: 51.235294 | AP6: 398 | AQ6: 71.7 | AR6: 555 | AV6: 409 | AW6: 57.2 | AX6: 715 | AY6: 380 | AZ6: 0 | BA6: 262
A7: 244 | B7: Xavier Smith | C7: LAR | D7: 0 | E7: 0 | F7: 0 | G7: 0 | H7: 0 | I7: 0 | J7: 0 | K7: 0 | L7: 0 | AP7: 398 | AQ7: 71.7 | AR7: 555 | AY7: 383 | AZ7: 0 | BA7: 0
A8: 259 | B8: Sam Wiglusz | C8: LAR | D8: 0 | E8: 0 | F8: 0 | G8: 0 | H8: 0 | I8: 0 | J8: 0 | K8: 0 | L8: 0 | AP8: 398 | AQ8: 71.7 | AR8: 555 | AY8: 383 | AZ8: 0 | BA8: 0
A9: 269 | B9: Drake Stoops | C9: LAR | D9: 0 | E9: 0 | F9: 0 | G9: 0 | H9: 0 | I9: 0 | J9: 0 | K9: 0 | L9: 0 | AP9: 398 | AQ9: 71.7 | AR9: 555 | AY9: 383 | AZ9: 0 | BA9: 0
A10: 294 | B10: Jordan Whittington | C10: LAR | D10: 0 | E10: 0 | F10: 0 | G10: 0 | H10: 0 | I10: 0 | J10: 0 | K10: 0 | L10: 0 | AP10: 398 | AQ10: 71.7 | AR10: 555 | AY10: 383 | AZ10: 0 | BA10: 0
A11: 11 | B11: Ja'Marr Chase | C11: CIN | D11: 100 | E11: 145 | F11: 1216 | G11: 14 | H11: 7 | I11: 3 | J11: 0 | K11: 16 | L11: 262.7 | M11: 11 | N11: 87 | O11: 134 | P11: 1046 | Q11: 13 | R11: 9 | S11: 5 | T11: 2 | U11: 13 | V11: 242.4 | W11: 5 | X11: 81 | Y11: 128 | Z11: 1455 | AA11: 22 | AB11: 13 | AC11: 7 | AD11: 1 | AE11: 17 | AF11: 304.6 | AG11: CIN | AH11: 87 | AI11: 81.882353 | AJ11: CIN | AK11: 93.916667 | AL11: 66.294118 | AM11: CIN | AN11: 84.529412 | AO11: 84.529412 | AP11: 387 | AQ11: 65.5 | AR11: 591 | AS11: 371 | AT11: 62 | AU11: 598 | AV11: 359 | AW11: 66.5 | AX11: 540 | AY11: 242 | AZ11: 227 | BA11: 216
A12: 51 | B12: Tee Higgins | C12: CIN | D12: 42 | E12: 76 | F12: 656 | G12: 8 | H12: 5 | I12: 0 | J12: 0 | K12: 12 | L12: 137.6 | M12: 18 | N12: 75 | O12: 110 | P12: 1042 | Q12: 14 | R12: 7 | S12: 0 | T12: 0 | U12: 15 | V12: 223.2 | W12: 24 | X12: 74 | Y12: 110 | Z12: 1091 | AA12: 17 | AB12: 6 | AC12: 0 | AD12: 1 | AE12: 14 | AF12: 219.1 | AG12: CIN | AH12: 73.833333 | AI12: 52.117647 | AJ12: CIN | AK12: 78.428571 | AL12: 64.588235 | AM12: CIN | AN12: 75.857143 | AO12: 62.470588 | AP12: 387 | AQ12: 65.5 | AR12: 591 | AS12: 371 | AT12: 62 | AU12: 598 | AV12: 359 | AW12: 66.5 | AX12: 540 | AY12: 311 | AZ12: 251 | BA12: 234
A13: 94 | B13: Trenton Irwin | C13: CIN | D13: 25 | E13: 32 | F13: 316 | G13: 7 | H13: 1 | I13: 0 | J13: 0 | K13: 16 | L13: 62.6 | M13: 102 | N13: 15 | O13: 23 | P13: 231 | Q13: 3 | R13: 4 | S13: 1 | T13: 0 | U13: 9 | V13: 63.2 | W13: 197 | X13: 2 | Y13: 5 | Z13: 34 | AA13: 1 | AB13: 0 | AC13: 0 | AD13: 0 | AE13: 5 | AF13: 5.4 | AG13: CIN | AH13: 42.6875 | AI13: 40.176471 | AJ13: CIN | AK13: 46.555556 | AL13: 24.647059 | AM13: CIN | AN13: 23.2 | AO13: 6.8235294 | AP13: 387 | AQ13: 65.5 | AR13: 591 | AS13: 371 | AT13: 62 | AU13: 598 | AV13: 359 | AW13: 66.5 | AX13: 540 | AY13: 355 | AZ13: 338 | BA13: 339
A14: 111 | B14: Andrei Iosivas | C14: CIN | D14: 15 | E14: 25 | F14: 116 | G14: 0 | H14: 4 | I14: 0 | J14: 0 | K14: 16 | L14: 50.6 | AG14: CIN | AH14: 25.9375 | AI14: 24.411765 | AP14: 387 | AQ14: 65.5 | AR14: 591 | AY14: 362 | AZ14: 0 | BA14: 0
A15: 157 | B15: Charlie Jones | C15: CIN | D15: 7 | E15: 9 | F15: 64 | G15: 1 | H15: 0 | I15: 2 | J15: 0 | K15: 11 | L15: 20.7 | AG15: CIN | AH15: 8.875 | AI15: 4.1764706 | AP15: 387 | AQ15: 65.5 | AR15: 591 | AY15: 378 | AZ15: 0 | BA15: 0
A16: 230 | B16: Shedrick Jackson | C16: CIN | D16: 0 | E16: 1 | F16: 0 | G16: 0 | H16: 0 | I16: 0 | J16: 0 | K16: 2 | L16: 0 | AG16: CIN | AH16: 8 | AI16: 0.47058824 | AP16: 387 | AQ16: 65.5 | AR16: 591 | AY16: 386 | AZ16: 0 | BA16: 0
A17: 264 | B17: Cole Burgess | C17: CIN | D17: 0 | E17: 0 | F17: 0 | G17: 0 | H17: 0 | I17: 0 | J17: 0 | K17: 0 | L17: 0 | AP17: 387 | AQ17: 65.5 | AR17: 591 | AY17: 387 | AZ17: 0 | BA17: 0
A18: 312 | B18: Jermaine Burton | C18: CIN | D18: 0 | E18: 0 | F18: 0 | G18: 0 | H18: 0 | I18: 0 | J18: 0 | K18: 0 | L18: 0 | AP18: 387 | AQ18: 65.5 | AR18: 591 | AY18: 387 | AZ18: 0 | BA18: 0
A19: 319 | B19: Kendric Pryor | C19: CIN | D19: 0 | E19: 0 | F19: 0 | G19: 0 | H19: 0 | I19: 0 | J19: 0 | K19: 0 | L19: 0 | AP19: 387 | AQ19: 65.5 | AR19: 591 | AY19: 387 | AZ19: 0 | BA19: 0
A20: 333 | B20: Maurice Purify | C20: CIN | D20: 0 | E20: 0 | F20: 0 | G20: 0 | H20: 0 | I20: 0 | J20: 0 | K20: 0 | L20: 0 | AP20: 387 | AQ20: 65.5 | AR20: 591 | AY20: 387 | AZ20: 0 | BA20: 0
A21: 338 | B21: Chris Henry | C21: CIN | D21: 0 | E21: 0 | F21: 0 | G21: 0 | H21: 0 | I21: 0 | J21: 0 | K21: 0 | L21: 0 | AP21: 387 | AQ21: 65.5 | AR21: 591 | AY21: 387 | AZ21: 0 | BA21: 0
A22: 74 | B22: Quentin Johnston | C22: LAC | D22: 38 | E22: 67 | F22: 431 | G22: 5 | H22: 2 | I22: 3 | J22: 0 | K22: 17 | L22: 94 | AG22: LAC | AH22: 65 | AI22: 65 | AP22: 386 | AQ22: 63 | AR22: 613 | AY22: 319 | AZ22: 0 | BA22: 0
A23: 59 | B23: DJ Chark Jr. | C23: LAC | D23: 35 | E23: 66 | F23: 525 | G23: 9 | H23: 5 | I23: 0 | J23: 1 | K23: 15 | L23: 115.5 | M23: 75 | N23: 30 | O23: 52 | P23: 502 | Q23: 9 | R23: 3 | S23: 0 | T23: 0 | U23: 11 | V23: 98.2 | W23: 135 | X23: 7 | Y23: 22 | Z23: 154 | AA23: 3 | AB23: 2 | AC23: 0 | AD23: 0 | AE23: 3 | AF23: 34.4 | AG23: CAR | AH23: 75.866667 | AI23: 66.941176 | AJ23: DET | AK23: 69.818182 | AL23: 45.176471 | AM23: JAC | AN23: 84 | AO23: 14.823529 | AP23: 386 | AQ23: 63 | AR23: 613 | AS23: 349 | AT23: 62.7 | AU23: 557 | AV23: 382 | AW23: 65.3 | AX23: 585 | AY23: 386 | AZ23: 293 | BA23: 310
A24: 65 | B24: Joshua Palmer | C24: LAC | D24: 38 | E24: 61 | F24: 581 | G24: 9 | H24: 2 | I24: 1 | J24: 1 | K24: 11 | L24: 106.7 | M24: 37 | N24: 72 | O24: 107 | P24: 769 | Q24: 7 | R24: 3 | S24: 1 | T24: 0 | U24: 16 | V24: 169.3 | W24: 76 | X24: 33 | Y24: 49 | Z24: 353 | AA24: 3 | AB24: 4 | AC24: 1 | AD24: 0 | AE24: 15 | AF24: 92.9 | AG24: LAC | AH24: 75.1 | AI24: 44.176471 | AJ24: LAC | AK24: 80.0625 | AL24: 75.352941 | AM24: LAC | AN24: 41.733333 | AO24: 36.823529 | AP24: 386 | AQ24: 63 | AR24: 613 | AS24: 381 | AT24: 55.6 | AU24: 685 | AV24: 390 | AW24: 59.3 | AX24: 658 | AY24: 325 | AZ24: 272 | BA24: 334
A25: 131 | B25: Derius Davis | C25: LAC | D25: 15 | E25: 17 | F25: 66 | G25: 0 | H25: 0 | I25: 14 | J25: 1 | K25: 17 | L25: 35.7 | AG25: LAC | AH25: 13.5625 | AI25: 12.764706 | AP25: 386 | AQ25: 63 | AR25: 613 | AY25: 369 | AZ25: 0 | BA25: 0
A26: 181 | B26: Simi Fehoko | C26: LAC | D26: 1 | E26: 2 | F26: 9 | G26: 0 | H26: 1 | I26: 0 | J26: 0 | K26: 5 | L26: 7.9 | M26: 182 | N26: 3 | O26: 4 | P26: 24 | Q26: 0 | R26: 0 | S26: 0 | T26: 0 | U26: 3 | V26: 5.4 | AG26: LAC | AH26: 9 | AI26: 2.1176471 | AJ26: DAL | AK26: 12.666667 | AL26: 2.2352941 | AP26: 386 | AQ26: 63 | AR26: 613 | AS26: 330 | AT26: 60.6 | AU26: 545 | AY26: 384 | AZ26: 309 | BA26: 0
A27: 261 | B27: Jaylen Johnson | C27: LAC | D27: 0 | E27: 0 | F27: 0 | G27: 0 | H27: 0 | I27: 0 | J27: 0 | K27: 0 | L27: 0 | AP27: 386 | AQ27: 63 | AR27: 613 | AY27: 386 | AZ27: 0 | BA27: 0
A28: 271 | B28: Ladd McConkey | C28: LAC | D28: 0 | E28: 0 | F28: 0 | G28: 0 | H28: 0 | I28: 0 | J28: 0 | K28: 0 | L28: 0 | AP28: 386 | AQ28: 63 | AR28: 613 | AY28: 386 | AZ28: 0 | BA28: 0
A29: 284 | B29: Brenden Rice | C29: LAC | D29: 0 | E29: 0 | F29: 0 | G29: 0 | H29: 0 | I29: 0 | J29: 0 | K29: 0 | L29: 0 | AP29: 386 | AQ29: 63 | AR29: 613 | AY29: 386 | AZ29: 0 | BA29: 0
A30: 308 | B30: Cornelius Johnson | C30: LAC | D30: 0 | E30: 0 | F30: 0 | G30: 0 | H30: 0 | I30: 0 | J30: 0 | K30: 0 | L30: 0 | AP30: 386 | AQ30: 63 | AR30: 613 | AY30: 386 | AZ30: 0 | BA30: 0
A31: 1 | B31: CeeDee Lamb | C31: DAL | D31: 135 | E31: 181 | F31: 1749 | G31: 29 | H31: 12 | I31: 14 | J31: 2 | K31: 17 | L31: 403.2 | M31: 5 | N31: 107 | O31: 156 | P31: 1359 | Q31: 24 | R31: 9 | S31: 10 | T31: 0 | U31: 17 | V31: 301.6 | W31: 19 | X31: 79 | Y31: 120 | Z31: 1102 | AA31: 20 | AB31: 6 | AC31: 9 | AD31: 0 | AE31: 16 | AF31: 232.8 | AG31: DAL | AH31: 83.705882 | AI31: 83.705882 | AJ31: DAL | AK31: 87.529412 | AL31: 87.529412 | AM31: DAL | AN31: 76.75 | AO31: 72.235294 | AP31: 379 | AQ31: 62.6 | AR31: 605 | AS31: 330 | AT31: 60.6 | AU31: 545 | AV31: 388 | AW31: 61 | AX31: 636 | AY31: 198 | AZ31: 157 | BA31: 268
A32: 38 | B32: Brandin Cooks | C32: DAL | D32: 54 | E32: 81 | F32: 657 | G32: 11 | H32: 8 | I32: 5 | J32: 0 | K32: 16 | L32: 173.2 | M32: 49 | N32: 57 | O32: 93 | P32: 699 | Q32: 13 | R32: 3 | S32: 2 | T32: 0 | U32: 13 | V32: 145.6 | W32: 20 | X32: 90 | Y32: 134 | Z32: 1037 | AA32: 12 | AB32: 6 | AC32: 2 | AD32: 0 | AE32: 16 | AF32: 231.8 | AG32: DAL | AH32: 73.3125 | AI32: 69 | AJ32: HOU | AK32: 81.153846 | AL32: 62.058824 | AM32: HOU | AN32: 83.25 | AO32: 78.352941 | AP32: 379 | AQ32: 62.6 | AR32: 605 | AS32: 294 | AT32: 52.8 | AU32: 557 | AV32: 319 | AW32: 61 | AX32: 523 | AY32: 298 | AZ32: 180 | BA32: 133
A33: 102 | B33: Jalen Tolbert | C33: DAL | D33: 22 | E33: 36 | F33: 268 | G33: 3 | H33: 2 | I33: 0 | J33: 1 | K33: 17 | L33: 58.8 | M33: 200 | N33: 2 | O33: 3 | P33: 12 | Q33: 0 | R33: 0 | S33: 0 | T33: 0 | U33: 3 | V33: 3.2 | AG33: DAL | AH33: 39.882353 | AI33: 39.882353 | AJ33: DAL | AK33: 21.333333 | AL33: 3.7647059 | AP33: 379 | AQ33: 62.6 | AR33: 605 | AS33: 330 | AT33: 60.6 | AU33: 545 | AY33: 343 | AZ33: 310 | BA33: 0
A34: 101 | B34: KaVontae Turpin | C34: DAL | D34: 12 | E34: 18 | F34: 127 | G34: 2 | H34: 3 | I34: 11 | J34: 0 | K34: 16 | L34: 59.7 | M34: 249 | N34: 1 | O34: 2 | P34: 9 | Q34: 0 | R34: 0 | S34: 3 | T34: 2 | U34: 17 | V34: -0.4 | AG34: DAL | AH34: 12.25 | AI34: 11.529412 | AJ34: DAL | AK34: 5.8125 | AL34: 5.4705882 | AP34: 379 | AQ34: 62.6 | AR34: 605 | AS34: 330 | AT34: 60.6 | AU34: 545 | AY34: 361 | AZ34: 311 | BA34: 0
A35: 170 | B35: Jalen Brooks | C35: DAL | D35: 6 | E35: 6 | F35: 64 | G35: 1 | H35: 0 | I35: 0 | J35: 0 | K35: 7 | L35: 12.4 | AG35: DAL | AH35: 15 | AI35: 6.1764706 | AP35: 379 | AQ35: 62.6 | AR35: 605 | AY35: 373 | AZ35: 0 | BA35: 0
A36: 234 | B36: John Stephens Jr. | C36: DAL | D36: 0 | E36: 0 | F36: 0 | G36: 0 | H36: 0 | I36: 0 | J36: 0 | K36: 0 | L36: 0 | AP36: 379 | AQ36: 62.6 | AR36: 605 | AY36: 379 | AZ36: 0 | BA36: 0
A37: 243 | B37: Jalen Moreno-Cropper | C37: DAL | D37: 0 | E37: 0 | F37: 0 | G37: 0 | H37: 0 | I37: 0 | J37: 0 | K37: 0 | L37: 0 | AP37: 379 | AQ37: 62.6 | AR37: 605 | AY37: 379 | AZ37: 0 | BA37: 0
A38: 257 | B38: Corey Crooms Jr. | C38: DAL | D38: 0 | E38: 0 | F38: 0 | G38: 0 | H38: 0 | I38: 0 | J38: 0 | K38: 0 | L38: 0 | AP38: 379 | AQ38: 62.6 | AR38: 605 | AY38: 379 | AZ38: 0 | BA38: 0
A39: 283 | B39: Ryan Flournoy | C39: DAL | D39: 0 | E39: 0 | F39: 0 | G39: 0 | H39: 0 | I39: 0 | J39: 0 | K39: 0 | L39: 0 | AP39: 379 | AQ39: 62.6 | AR39: 605 | AY39: 379 | AZ39: 0 | BA39: 0
A40: 346 | B40: Kelvin Harmon | C40: DAL | D40: 0 | E40: 0 | F40: 0 | G40: 0 | H40: 0 | I40: 0 | J40: 0 | K40: 0 | L40: 0 | AP40: 379 | AQ40: 62.6 | AR40: 605 | AY40: 379 | AZ40: 0 | BA40: 0
...

Sheet TE
A1: rank | B1: player | C1: rec | D1: tgt | E1: yds | F1: 20+ | G1: td | H1: att | I1: fl | J1: g | K1: fpts | L1: team | M1: rank_1 | N1: rec_1 | O1: tgt_1 | P1: yds_1 | Q1: 20+_1 | R1: td_1 | S1: att_1 | T1: fl_1 | U1: g_1 | V1: fpts_1 | W1: rank_2 | X1: rec_2 | Y1: tgt_2 | Z1: yds_2 | AA1: 20+_2 | AB1: td_2 | AC1: att_2 | AD1: fl_2 | AE1: g_2 | AF1: fpts_2 | AG1: team_0 | AH1: avg_snap_pct_played | AI1: avg_snap_pct_global | AJ1: team_1 | AK1: avg_snap_pct_played_1 | AL1: avg_snap_pct_global_1 | AM1: team_2 | AN1: avg_snap_pct_played_2 | AO1: avg_snap_pct_global_2 | AP1: te_targets | AQ1: te_pct | AR1: total_targets | AS1: te_targets_1 | AT1: te_pct_1 | AU1: total_targets_1 | AV1: te_targets_2 | AW1: te_pct_2 | AX1: total_targets_2 | AY1: tgt_teammates | AZ1: tgt_teammates_1 | BA1: tgt_teammates_2
A2: 1 | B2: Sam LaPorta | C2: 86 | D2: 120 | E2: 889 | F2: 8 | G2: 10 | H2: 1 | I2: 0 | J2: 17 | K2: 239.3 | L2: DET | AG2: DET | AH2: 82.588235 | AI2: 82.588235 | AP2: 136 | AQ2: 23.8 | AR2: 571 | AY2: 16 | AZ2: 0 | BA2: 0
A3: 2 | B3: Evan Engram | C3: 114 | D3: 143 | E3: 963 | F3: 9 | G3: 4 | H3: 0 | I3: 2 | J3: 17 | K3: 230.3 | L3: JAC | M3: 5 | N3: 73 | O3: 98 | P3: 766 | Q3: 10 | R3: 4 | S3: 2 | T3: 0 | U3: 17 | V3: 176.9 | W3: 23 | X3: 46 | Y3: 73 | Z3: 408 | AA3: 2 | AB3: 3 | AC3: 1 | AD3: 1 | AE3: 15 | AF3: 102.5 | AG3: JAC | AH3: 78.647059 | AI3: 78.647059 | AJ3: JAC | AK3: 77.470588 | AL3: 77.470588 | AM3: NYG | AN3: 74.666667 | AO3: 65.882353 | AP3: 167 | AQ3: 27.5 | AR3: 607 | AS3: 123 | AT3: 21.4 | AU3: 575 | AV3: 121 | AW3: 21.6 | AX3: 561 | AY3: 24 | AZ3: 12 | BA3: 0
A4: 3 | B4: Travis Kelce | C4: 93 | D4: 121 | E4: 984 | F4: 12 | G4: 5 | H4: 0 | I4: 1 | J4: 15 | K4: 219.4 | L4: KC | M4: 1 | N4: 110 | O4: 152 | P4: 1338 | Q4: 19 | R4: 12 | S4: 2 | T4: 1 | U4: 17 | V4: 316.3 | W4: 2 | X4: 92 | Y4: 134 | Z4: 1125 | AA4: 13 | AB4: 9 | AC4: 2 | AD4: 1 | AE4: 16 | AF4: 262.8 | AG4: KC | AH4: 77 | AI4: 67.941176 | AJ4: KC | AK4: 79.588235 | AL4: 79.588235 | AM4: KC | AN4: 82.125 | AO4: 77.294118 | AP4: 171 | AQ4: 28.6 | AR4: 598 | AS4: 201 | AT4: 32.8 | AU4: 613 | AV4: 162 | AW4: 25.5 | AX4: 636 | AY4: 50 | AZ4: 36 | BA4: 23
A5: 4 | B5: T.J. Hockenson | C5: 95 | D5: 127 | E5: 960 | F5: 13 | G5: 5 | H5: 0 | I5: 1 | J5: 15 | K5: 219 | L5: MIN | M5: 2 | N5: 86 | O5: 129 | P5: 914 | Q5: 5 | R5: 6 | S5: 0 | T5: 1 | U5: 17 | V5: 215.4 | W5: 15 | X5: 61 | Y5: 84 | Z5: 583 | AA5: 8 | AB5: 4 | AC5: 0 | AD5: 0 | AE5: 12 | AF5: 145.3 | AG5: MIN | AH5: 79.066667 | AI5: 69.764706 | AJ5: MIN | AK5: 84.470588 | AL5: 79.777778 | AM5: DET | AN5: 83.916667 | AO5: 59.235294 | AP5: 179 | AQ5: 29.5 | AR5: 606 | AS5: 146 | AT5: 22.8 | AU5: 641 | AV5: 113 | AW5: 20.4 | AX5: 554 | AY5: 52 | AZ5: 57 | BA5: 24
A6: 5 | B6: George Kittle | C6: 65 | D6: 90 | E6: 1020 | F6: 18 | G6: 6 | H6: 1 | I6: 0 | J6: 16 | K6: 203.2 | L6: SF | M6: 3 | N6: 60 | O6: 86 | P6: 765 | Q6: 12 | R6: 11 | S6: 0 | T6: 1 | U6: 15 | V6: 200.5 | W6: 4 | X6: 71 | Y6: 94 | Z6: 910 | AA6: 13 | AB6: 6 | AC6: 3 | AD6: 1 | AE6: 14 | AF6: 198 | AG6: SF | AH6: 89.5 | AI6: 84.235294 | AJ6: SF | AK6: 89.6 | AL6: 79.058824 | AM6: SF | AN6: 91.857143 | AO6: 75.647059 | AP6: 95 | AQ6: 20.2 | AR6: 471 | AS6: 98 | AT6: 19.4 | AU6: 504 | AV6: 105 | AW6: 21.2 | AX6: 496 | AY6: 8 | AZ6: 12 | BA6: 11
A7: 6 | B7: David Njoku | C7: 81 | D7: 123 | E7: 882 | F7: 12 | G7: 6 | H7: 0 | I7: 2 | J7: 16 | K7: 201.2 | L7: CLE | M7: 11 | N7: 58 | O7: 80 | P7: 628 | Q7: 8 | R7: 4 | S7: 2 | T7: 1 | U7: 14 | V7: 142 | W7: 22 | X7: 36 | Y7: 53 | Z7: 475 | AA7: 8 | AB7: 4 | AC7: 1 | AD7: 0 | AE7: 15 | AF7: 107.6 | AG7: CLE | AH7: 81.625 | AI7: 76.823529 | AJ7: CLE | AK7: 84.285714 | AL7: 69.411765 | AM7: CLE | AN7: 64.8 | AO7: 57.176471 | AP7: 166 | AQ7: 27.8 | AR7: 597 | AS7: 133 | AT7: 26.3 | AU7: 506 | AV7: 142 | AW7: 28.5 | AX7: 499 | AY7: 43 | AZ7: 43 | BA7: 89
A8: 7 | B8: Trey McBride | C8: 81 | D8: 106 | E8: 825 | F8: 9 | G8: 3 | H8: 0 | I8: 0 | J8: 17 | K8: 181.5 | L8: ARI | M8: 40 | N8: 29 | O8: 39 | P8: 265 | Q8: 3 | R8: 1 | S8: 0 | T8: 0 | U8: 12 | V8: 61.5 | AG8: ARI | AH8: 68.941176 | AI8: 68.941176 | AJ8: ARI | AK8: 68 | AL8: 48 | AP8: 179 | AQ8: 33.1 | AR8: 540 | AS8: 118 | AT8: 18.6 | AU8: 634 | AY8: 73 | AZ8: 76 | BA8: 0
A9: 8 | B9: Cole Kmet | C9: 73 | D9: 90 | E9: 719 | F9: 9 | G9: 6 | H9: 3 | I9: 0 | J9: 17 | K9: 181.1 | L9: CHI | M9: 8 | N9: 50 | O9: 69 | P9: 544 | Q9: 6 | R9: 7 | S9: 2 | T9: 0 | U9: 17 | V9: 147.3 | W9: 20 | X9: 60 | Y9: 93 | Z9: 612 | AA9: 7 | AB9: 0 | AC9: 1 | AD9: 0 | AE9: 17 | AF9: 121.2 | AG9: CHI | AH9: 77.117647 | AI9: 77.117647 | AJ9: CHI | AK9: 93.529412 | AL9: 93.529412 | AM9: CHI | AN9: 83.647059 | AO9: 83.647059 | AP9: 112 | AQ9: 23.5 | AR9: 477 | AS9: 82 | AT9: 22.8 | AU9: 359 | AV9: 127 | AW9: 24.2 | AX9: 524 | AY9: 22 | AZ9: 5 | BA9: 26
A10: 9 | B10: Jake Ferguson | C10: 71 | D10: 102 | E10: 761 | F10: 8 | G10: 5 | H10: 0 | I10: 0 | J10: 17 | K10: 177.1 | L10: DAL | M10: 48 | N10: 19 | O10: 22 | P10: 174 | Q10: 3 | R10: 2 | S10: 0 | T10: 0 | U10: 11 | V10: 48.4 | AG10: DAL | AH10: 74.647059 | AI10: 74.647059 | AJ10: DAL | AK10: 42.818182 | AL10: 27.705882 | AP10: 126 | AQ10: 20.8 | AR10: 605 | AS10: 130 | AT10: 23.9 | AU10: 545 | AY10: 24 | AZ10: 108 | BA10: 0
A11: 10 | B11: Dalton Schultz | C11: 59 | D11: 88 | E11: 635 | F11: 7 | G11: 5 | H11: 0 | I11: 1 | J11: 15 | K11: 150.5 | L11: HOU | M11: 10 | N11: 57 | O11: 89 | P11: 577 | Q11: 5 | R11: 5 | S11: 0 | T11: 1 | U11: 15 | V11: 142.7 | W11: 3 | X11: 78 | Y11: 104 | Z11: 808 | AA11: 6 | AB11: 8 | AC11: 0 | AD11: 0 | AE11: 17 | AF11: 208.8 | AG11: HOU | AH11: 72.666667 | AI11: 64.117647 | AJ11: DAL | AK11: 78.266667 | AL11: 69.058824 | AM11: DAL | AN11: 81.058824 | AO11: 81.058824 | AP11: 128 | AQ11: 22.7 | AR11: 565 | AS11: 130 | AT11: 23.9 | AU11: 545 | AV11: 130 | AW11: 20.4 | AX11: 636 | AY11: 37 | AZ11: 41 | BA11: 6
A12: 11 | B12: Dalton Kincaid | C12: 73 | D12: 91 | E12: 673 | F12: 5 | G12: 2 | H12: 0 | I12: 1 | J12: 16 | K12: 150.3 | L12: BUF | AG12: BUF | AH12: 63.375 | AI12: 59.647059 | AP12: 130 | AQ12: 23.9 | AR12: 545 | AY12: 39 | AZ12: 0 | BA12: 0
A13: 12 | B13: Taysom Hill | C13: 33 | D13: 40 | E13: 291 | F13: 2 | G13: 2 | H13: 81 | I13: 1 | J13: 16 | K13: 143.5 | L13: NO | M13: 9 | N13: 9 | O13: 13 | P13: 77 | Q13: 1 | R13: 2 | S13: 96 | T13: 0 | U13: 16 | V13: 145.8 | W13: 138 | X13: 4 | Y13: 6 | Z13: 52 | AA13: 0 | AB13: 0 | AC13: 70 | AD13: 0 | AE13: 12 | AF13: 0 | AG13: NO | AH13: 37.5625 | AI13: 35.352941 | AJ13: NO | AK13: 33.875 | AL13: 31.882353 | AM13: NO | AN13: 55.5 | AO13: 39.176471 | AP13: 131 | AQ13: 22.6 | AR13: 579 | AS13: 102 | AT13: 20.7 | AU13: 493 | AV13: 92 | AW13: 19.4 | AX13: 474 | AY13: 91 | AZ13: 87 | BA13: 80
A14: 13 | B14: Kyle Pitts | C14: 53 | D14: 90 | E14: 667 | F14: 7 | G14: 3 | H14: 1 | I14: 0 | J14: 17 | K14: 137.3 | L14: ATL | M14: 33 | N14: 28 | O14: 59 | P14: 356 | Q14: 5 | R14: 2 | S14: 0 | T14: 0 | U14: 10 | V14: 75.6 | W14: 6 | X14: 68 | Y14: 110 | Z14: 1026 | AA14: 16 | AB14: 1 | AC14: 0 | AD14: 0 | AE14: 17 | AF14: 176.6 | AG14: ATL | AH14: 64.470588 | AI14: 64.470588 | AJ14: ATL | AK14: 71.9 | AL14: 42.294118 | AM14: ATL | AN14: 73.529412 | AO14: 73.529412 | AP14: 174 | AQ14: 34.3 | AR14: 507 | AS14: 104 | AT14: 26.1 | AU14: 398 | AV14: 158 | AW14: 28.5 | AX14: 555 | AY14: 84 | AZ14: 45 | BA14: 37
A15: 14 | B15: Dallas Goedert | C15: 59 | D15: 83 | E15: 592 | F15: 6 | G15: 3 | H15: 1 | I15: 0 | J15: 14 | K15: 136.3 | L15: PHI | M15: 12 | N15: 55 | O15: 69 | P15: 702 | Q15: 11 | R15: 3 | S15: 0 | T15: 1 | U15: 12 | V15: 141.2 | W15: 8 | X15: 56 | Y15: 76 | Z15: 830 | AA15: 14 | AB15: 4 | AC15: 0 | AD15: 0 | AE15: 15 | AF15: 165 | AG15: PHI | AH15: 84.5 | AI15: 69.588235 | AJ15: PHI | AK15: 90 | AL15: 63.529412 | AM15: PHI | AN15: 78.066667 | AO15: 68.882353 | AP15: 96 | AQ15: 18.3 | AR15: 525 | AS15: 93 | AT15: 18.4 | AU15: 505 | AV15: 121 | AW15: 26 | AX15: 466 | AY15: 13 | AZ15: 24 | BA15: 12
A16: 15 | B16: Mark Andrews | C16: 45 | D16: 61 | E16: 544 | F16: 8 | G16: 6 | H16: 1 | I16: 0 | J16: 10 | K16: 135.4 | L16: BAL | M16: 4 | N16: 73 | O16: 113 | P16: 847 | Q16: 7 | R16: 5 | S16: 3 | T16: 0 | U16: 15 | V16: 190.5 | W16: 1 | X16: 107 | Y16: 153 | Z16: 1361 | AA16: 20 | AB16: 9 | AC16: 1 | AD16: 0 | AE16: 17 | AF16: 301.1 | AG16: BAL | AH16: 69.8 | AI16: 41.058824 | AJ16: BAL | AK16: 83.866667 | AL16: 74 | AM16: BAL | AN16: 75.588235 | AO16: 75.588235 | AP16: 110 | AQ16: 23.1 | AR16: 476 | AS16: 204 | AT16: 43.9 | AU16: 465 | AV16: 172 | AW16: 29.1 | AX16: 592 | AY16: 49 | AZ16: 91 | BA16: 17
A17: 16 | B17: Logan Thomas | C17: 55 | D17: 78 | E17: 496 | F17: 3 | G17: 4 | H17: 1 | I17: 2 | J17: 16 | K17: 126.8 | L17: FA | M17: 32 | N17: 39 | O17: 61 | P17: 323 | Q17: 2 | R17: 1 | S17: 0 | T17: 0 | U17: 13 | V17: 77.3 | W17: 44 | X17: 18 | Y17: 25 | Z17: 196 | AA17: 2 | AB17: 3 | AC17: 0 | AD17: 1 | AE17: 5 | AF17: 53.6 | AG17: WAS | AH17: 69.1875 | AI17: 65.117647 | AJ17: WAS | AK17: 69.307692 | AL17: 53 | AM17: WAS | AN17: 88.6 | AO17: 26.058824 | AS17: 98 | AT17: 18.5 | AU17: 531 | AV17: 99 | AW17: 18.5 | AX17: 534 | AY17: 0 | AZ17: 31 | BA17: 25
A18: 17 | B18: Jonnu Smith | C18: 50 | D18: 70 | E18: 582 | F18: 4 | G18: 3 | H18: 1 | I18: 1 | J18: 17 | K18: 124.2 | L18: MIA | M18: 47 | N18: 27 | O18: 38 | P18: 245 | Q18: 3 | R18: 0 | S18: 1 | T18: 0 | U18: 12 | V18: 52 | W18: 35 | X18: 28 | Y18: 45 | Z18: 294 | AA18: 5 | AB18: 1 | AC18: 9 | AD18: 0 | AE18: 16 | AF18: 67.4 | AG18: ATL | AH18: 57.352941 | AI18: 57.352941 | AJ18: NE | AK18: 51.166667 | AL18: 36.117647 | AM18: NE | AN18: 51.125 | AO18: 48.117647 | AP18: 52 | AQ18: 9.5 | AR18: 549 | AS18: 97 | AT18: 18.9 | AU18: 513 | AV18: 120 | AW18: 22.9 | AX18: 523 | AY18: 52 | AZ18: 79 | BA18: 75
A19: 18 | B19: Tyler Conklin | C19: 61 | D19: 87 | E19: 621 | F19: 7 | G19: 0 | H19: 1 | I19: 0 | J19: 17 | K19: 123.1 | L19: NYJ | M19: 16 | N19: 58 | O19: 87 | P19: 552 | Q19: 6 | R19: 3 | S19: 2 | T19: 0 | U19: 17 | V19: 131.5 | W19: 16 | X19: 61 | Y19: 87 | Z19: 593 | AA19: 4 | AB19: 3 | AC19: 0 | AD19: 0 | AE19: 17 | AF19: 138.3 | AG19: NYJ | AH19: 70.235294 | AI19: 70.235294 | AJ19: NYJ | AK19: 77 | AL19: 77 | AM19: MIN | AN19: 81 | AO19: 81 | AP19: 125 | AQ19: 22.2 | AR19: 562 | AS19: 116 | AT19: 19.8 | AU19: 587 | AV19: 97 | AW19: 16.8 | AX19: 577 | AY19: 38 | AZ19: 29 | BA19: 0
A20: 19 | B20: Hunter Henry | C20: 42 | D20: 61 | E20: 419 | F20: 2 | G20: 6 | H20: 0 | I20: 0 | J20: 14 | K20: 119.9 | L20: NE | M20: 22 | N20: 41 | O20: 59 | P20: 509 | Q20: 10 | R20: 2 | S20: 0 | T20: 0 | U20: 16 | V20: 103.9 | W20: 10 | X20: 50 | Y20: 75 | Z20: 603 | AA20: 8 | AB20: 9 | AC20: 0 | AD20: 0 | AE20: 16 | AF20: 164.3 | AG20: NE | AH20: 74.714286 | AI20: 61.529412 | AJ20: NE | AK20: 80 | AL20: 75.294118 | AM20: NE | AN20: 69.625 | AO20: 65.529412 | AP20: 121 | AQ20: 22.4 | AR20: 541 | AS20: 97 | AT20: 18.9 | AU20: 513 | AV20: 120 | AW20: 22.9 | AX20: 523 | AY20: 60 | AZ20: 58 | BA20: 45
A21: 20 | B21: Cade Otton | C21: 47 | D21: 67 | E21: 455 | F21: 6 | G21: 4 | H21: 0 | I21: 1 | J21: 17 | K21: 116.5 | L21: TB | M21: 26 | N21: 42 | O21: 65 | P21: 391 | Q21: 4 | R21: 2 | S21: 0 | T21: 0 | U21: 16 | V21: 93.1 | AG21: TB | AH21: 96.235294 | AI21: 96.235294 | AJ21: TB | AK21: 68.5 | AL21: 64.470588 | AP21: 81 | AQ21: 14.7 | AR21: 550 | AS21: 118 | AT21: 16.3 | AU21: 723 | AY21: 14 | AZ21: 10 | BA21: 0
A22: 21 | B22: Chigoziem Okonkwo | C22: 54 | D22: 77 | E22: 528 | F22: 6 | G22: 1 | H22: 2 | I22: 0 | J22: 17 | K22: 113.4 | L22: TEN | M22: 25 | N22: 32 | O22: 46 | P22: 450 | Q22: 7 | R22: 3 | S22: 3 | T22: 0 | U22: 16 | V22: 97.2 | AG22: TEN | AH22: 65.470588 | AI22: 65.470588 | AJ22: TEN | AK22: 37.5625 | AL22: 35.352941 | AP22: 98 | AQ22: 20.6 | AR22: 476 | AS22: 122 | AT22: 28 | AU22: 436 | AY22: 21 | AZ22: 76 | BA22: 0
A23: 22 | B23: Darren Waller | C23: 52 | D23: 74 | E23: 552 | F23: 8 | G23: 1 | H23: 0 | I23: 0 | J23: 12 | K23: 113.2 | L23: FA | M23: 31 | N23: 28 | O23: 43 | P23: 388 | Q23: 9 | R23: 3 | S23: 0 | T23: 0 | U23: 9 | V23: 84.8 | W23: 17 | X23: 55 | Y23: 93 | Z23: 665 | AA23: 13 | AB23: 2 | AC23: 0 | AD23: 0 | AE23: 11 | AF23: 133.5 | AG23: NYG | AH23: 69.083333 | AI23: 48.764706 | AJ23: LV | AK23: 63.125 | AL23: 29.705882 | AM23: LV | AN23: 82.909091 | AO23: 53.647059 | AS23: 101 | AT23: 18.1 | AU23: 559 | AV23: 141 | AW23: 23.4 | AX23: 603 | AY23: 0 | AZ23: 58 | BA23: 44
A24: 23 | B24: Gerald Everett | C24: 51 | D24: 70 | E24: 411 | F24: 4 | G24: 3 | H24: 3 | I24: 0 | J24: 15 | K24: 111.1 | L24: CHI | M24: 13 | N24: 58 | O24: 87 | P24: 555 | Q24: 4 | R24: 4 | S24: 1 | T24: 0 | U24: 15 | V24: 139.5 | W24: 21 | X24: 48 | Y24: 63 | Z24: 478 | AA24: 5 | AB24: 4 | AC24: 3 | AD24: 2 | AE24: 15 | AF24: 117.8 | AG24: LAC | AH24: 56.6 | AI24: 49.941176 | AJ24: LAC | AK24: 59.066667 | AL24: 52.117647 | AM24: SEA | AN24: 75.2 | AO24: 66.352941 | AP24: 112 | AQ24: 23.5 | AR24: 477 | AS24: 126 | AT24: 18.4 | AU24: 685 | AV24: 97 | AW24: 20.5 | AX24: 473 | AY24: 112 | AZ24: 44 | BA24: 34
A25: 24 | B25: Tyler Higbee | C25: 47 | D25: 70 | E25: 495 | F25: 6 | G25: 2 | H25: 0 | I25: 0 | J25: 15 | K25: 108.5 | L25: LAR | M25: 6 | N25: 72 | O25: 108 | P25: 620 | Q25: 4 | R25: 3 | S25: 0 | T25: 0 | U25: 16 | V25: 152 | W25: 14 | X25: 61 | Y25: 85 | Z25: 560 | AA25: 3 | AB25: 5 | AC25: 0 | AD25: 0 | AE25: 15 | AF25: 147 | AG25: LAR | AH25: 86.533333 | AI25: 76.352941 | AJ25: LAR | AK25: 88.1875 | AL25: 83 | AM25: LAR | AN25: 91.8 | AO25: 81 | AP25: 88 | AQ25: 15.9 | AR25: 555 | AS25: 122 | AT25: 23.6 | AU25: 516 | AV25: 94 | AW25: 15.6 | AX25: 602 | AY25: 18 | AZ25: 11 | BA25: 2
A26: 25 | B26: Isaiah Likely | C26: 30 | D26: 40 | E26: 411 | F26: 6 | G26: 5 | H26: 0 | I26: 0 | J26: 17 | K26: 101.1 | L26: BAL | M26: 27 | N26: 36 | O26: 60 | P26: 373 | Q26: 4 | R26: 3 | S26: 0 | T26: 0 | U26: 14 | V26: 91.3 | AG26: BAL | AH26: 43.647059 | AI26: 43.647059 | AJ26: BAL | AK26: 40.071429 | AL26: 33 | AP26: 110 | AQ26: 23.1 | AR26: 476 | AS26: 204 | AT26: 43.9 | AU26: 465 | AY26: 70 | AZ26: 144 | BA26: 0
A27: 26 | B27: Juwan Johnson | C27: 37 | D27: 59 | E27: 368 | F27: 7 | G27: 4 | H27: 0 | I27: 0 | J27: 13 | K27: 97.8 | L27: NO | M27: 15 | N27: 42 | O27: 65 | P27: 508 | Q27: 8 | R27: 7 | S27: 0 | T27: 0 | U27: 16 | V27: 134.8 | W27: 46 | X27: 13 | Y27: 22 | Z27: 159 | AA27: 3 | AB27: 4 | AC27: 0 | AD27: 0 | AE27: 13 | AF27: 52.9 | AG27: NO | AH27: 64.769231 | AI27: 49.529412 | AJ27: NO | AK27: 64.8125 | AL27: 61 | AM27: NO | AN27: 25.692308 | AO27: 19.647059 | AP27: 131 | AQ27: 22.6 | AR27: 579 | AS27: 102 | AT27: 20.7 | AU27: 493 | AV27: 92 | AW27: 19.4 | AX27: 474 | AY27: 72 | AZ27: 35 | BA27: 64
A28: 27 | B28: Tanner Hudson | C28: 39 | D28: 50 | E28: 352 | F28: 3 | G28: 1 | H28: 0 | I28: 0 | J28: 12 | K28: 80.2 | L28: CIN | M28: 75 | N28: 10 | O28: 15 | P28: 132 | Q28: 1 | R28: 0 | S28: 0 | T28: 0 | U28: 6 | V28: 23.2 | AG28: CIN | AH28: 35.5 | AI28: 25.058824 | AJ28: NYG | AK28: 40.5 | AL28: 14.294118 | AP28: 115 | AQ28: 19.5 | AR28: 591 | AS28: 65 | AT28: 13.3 | AU28: 489 | AY28: 65 | AZ28: 35 | BA28: 0
A29: 28 | B29: Donald Parham Jr. | C29: 27 | D29: 41 | E29: 285 | F29: 2 | G29: 4 | H29: 0 | I29: 0 | J29: 14 | K29: 79.5 | L29: DEN | M29: 65 | N29: 10 | O29: 12 | P29: 130 | Q29: 2 | R29: 1 | S29: 0 | T29: 0 | U29: 6 | V29: 29 | W29: 42 | X29: 20 | Y29: 27 | Z29: 190 | AA29: 1 | AB29: 3 | AC29: 0 | AD29: 0 | AE29: 14 | AF29: 59 | AG29: LAC | AH29: 47.928571 | AI29: 39.470588 | AJ29: LAC | AK29: 33.833333 | AL29: 11.941176 | AM29: LAC | AN29: 41.142857 | AO29: 33.882353 | AP29: 62 | AQ29: 13 | AR29: 477 | AS29: 126 | AT29: 18.4 | AU29: 685 | AV29: 137 | AW29: 20.8 | AX29: 658 | AY29: 62 | AZ29: 119 | BA29: 27
A30: 29 | B30: Tucker Kraft | C30: 31 | D30: 40 | E30: 355 | F30: 5 | G30: 2 | H30: 0 | I30: 0 | J30: 17 | K30: 78.5 | L30: GB | AG30: GB | AH30: 56.588235 | AI30: 56.588235 | AP30: 100 | AQ30: 17.8 | AR30: 561 | AY30: 60 | AZ30: 0 | BA30: 0
A31: 30 | B31: Pat Freiermuth | C31: 32 | D31: 47 | E31: 308 | F31: 3 | G31: 2 | H31: 0 | I31: 0 | J31: 12 | K31: 76.8 | L31: PIT | M31: 7 | N31: 63 | O31: 98 | P31: 732 | Q31: 9 | R31: 2 | S31: 0 | T31: 0 | U31: 15 | V31: 148.2 | W31: 13 | X31: 60 | Y31: 79 | Z31: 497 | AA31: 2 | AB31: 7 | AC31: 0 | AD31: 1 | AE31: 16 | AF31: 151.7 | AG31: PIT | AH31: 63.416667 | AI31: 44.764706 | AJ31: PIT | AK31: 68.8 | AL31: 60.705882 | AM31: PIT | AN31: 61.625 | AO31: 58 | AP31: 93 | AQ31: 19.2 | AR31: 484 | AS31: 138 | AT31: 25.2 | AU31: 548 | AV31: 125 | AW31: 19.1 | AX31: 653 | AY31: 46 | AZ31: 40 | BA31: 28
A32: 31 | B32: Luke Musgrave | C32: 34 | D32: 46 | E32: 352 | F32: 5 | G32: 1 | H32: 0 | I32: 0 | J32: 11 | K32: 75.2 | L32: GB | AG32: GB | AH32: 65.272727 | AI32: 42.235294 | AP32: 100 | AQ32: 17.8 | AR32: 561 | AY32: 54 | AZ32: 0 | BA32: 0
A33: 32 | B33: Noah Fant | C33: 32 | D33: 43 | E33: 414 | F33: 7 | G33: 0 | H33: 0 | I33: 0 | J33: 17 | K33: 73.4 | L33: SEA | M33: 17 | N33: 50 | O33: 63 | P33: 486 | Q33: 4 | R33: 4 | S33: 0 | T33: 0 | U33: 17 | V33: 122.6 | W33: 12 | X33: 68 | Y33: 90 | Z33: 670 | AA33: 7 | AB33: 4 | AC33: 0 | AD33: 0 | AE33: 16 | AF33: 159 | AG33: SEA | AH33: 54.176471 | AI33: 54.176471 | AJ33: SEA | AK33: 60 | AL33: 60 | AM33: DEN | AN33: 84.4375 | AO33: 79.470588 | AP33: 99 | AQ33: 18.1 | AR33: 546 | AS33: 136 | AT33: 24.6 | AU33: 553 | AV33: 142 | AW33: 27.5 | AX33: 516 | AY33: 56 | AZ33: 73 | BA33: 52
A34: 33 | B34: Kylen Granson | C34: 30 | D34: 50 | E34: 368 | F34: 5 | G34: 1 | H34: 1 | I34: 0 | J34: 15 | K34: 73 | L34: IND | M34: 41 | N34: 31 | O34: 40 | P34: 302 | Q34: 3 | R34: 0 | S34: 1 | T34: 0 | U34: 13 | V34: 61.2 | W34: 67 | X34: 11 | Y34: 15 | Z34: 106 | AA34: 1 | AB34: 0 | AC34: 0 | AD34: 0 | AE34: 10 | AF34: 21.6 | AG34: IND | AH34: 49.466667 | AI34: 43.647059 | AJ34: IND | AK34: 45.076923 | AL34: 34.470588 | AM34: IND | AN34: 23.5 | AO34: 13.823529 | AP34: 119 | AQ34: 21.8 | AR34: 546 | AS34: 108 | AT34: 18.7 | AU34: 579 | AV34: 103 | AW34: 20.6 | AX34: 501 | AY34: 69 | AZ34: 68 | BA34: 45
A35: 34 | B35: Durham Smythe | C35: 35 | D35: 43 | E35: 366 | F35: 3 | G35: 0 | H35: 0 | I35: 0 | J35: 16 | K35: 71.6 | L35: MIA | M35: 53 | N35: 15 | O35: 20 | P35: 129 | Q35: 1 | R35: 1 | S35: 2 | T35: 0 | U35: 13 | V35: 40 | W35: 33 | X35: 34 | Y35: 41 | Z35: 357 | AA35: 5 | AB35: 0 | AC35: 2 | AD35: 0 | AE35: 16 | AF35: 70 | AG35: MIA | AH35: 77.0625 | AI35: 72.529412 | AJ35: MIA | AK35: 59.692308 | AL35: 45.647059 | AM35: MIA | AN35: 63.5 | AO35: 59.764706 | AP35: 52 | AQ35: 9.5 | AR35: 549 | AS35: 75 | AT35: 13.3 | AU35: 562 | AV35: 174 | AW35: 29.1 | AX35: 597 | AY35: 9 | AZ35: 55 | BA35: 115
A36: 35 | B36: Michael Mayer | C36: 27 | D36: 40 | E36: 304 | F36: 2 | G36: 2 | H36: 0 | I36: 0 | J36: 14 | K36: 71.4 | L36: LV | AG36: LV | AH36: 71 | AI36: 58.470588 | AP36: 73 | AQ36: 13.7 | AR36: 531 | AY36: 33 | AZ36: 0 | BA36: 0
A37: 36 | B37: Noah Gray | C37: 28 | D37: 41 | E37: 305 | F37: 4 | G37: 2 | H37: 1 | I37: 0 | J37: 17 | K37: 70.6 | L37: KC | M37: 36 | N37: 28 | O37: 34 | P37: 299 | Q37: 3 | R37: 1 | S37: 1 | T37: 0 | U37: 17 | V37: 70 | W37: 76 | X37: 7 | Y37: 10 | Z37: 36 | AA37: 0 | AB37: 1 | AC37: 0 | AD37: 0 | AE37: 7 | AF37: 16.6 | AG37: KC | AH37: 52.647059 | AI37: 52.647059 | AJ37: KC | AK37: 52.235294 | AL37: 52.235294 | AM37: KC | AN37: 31.285714 | AO37: 12.882353 | AP37: 171 | AQ37: 28.6 | AR37: 598 | AS37: 201 | AT37: 32.8 | AU37: 613 | AV37: 162 | AW37: 25.5 | AX37: 636 | AY37: 130 | AZ37: 154 | BA37: 147
A38: 37 | B38: Mike Gesicki | C38: 29 | D38: 45 | E38: 244 | F38: 0 | G38: 2 | H38: 0 | I38: 0 | J38: 17 | K38: 65.4 | L38: CIN | M38: 23 | N38: 32 | O38: 52 | P38: 362 | Q38: 5 | R38: 5 | S38: 0 | T38: 0 | U38: 17 | V38: 98.2 | W38: 9 | X38: 73 | Y38: 112 | Z38: 780 | AA38: 12 | AB38: 2 | AC38: 0 | AD38: 0 | AE38: 17 | AF38: 165 | AG38: NE | AH38: 50.294118 | AI38: 50.294118 | AJ38: MIA | AK38: 43.823529 | AL38: 43.823529 | AM38: MIA | AN38: 71.411765 | AO38: 71.411765 | AP38: 115 | AQ38: 19.5 | AR38: 591 | AS38: 75 | AT38: 13.3 | AU38: 562 | AV38: 174 | AW38: 29.1 | AX38: 597 | AY38: 115 | AZ38: 23 | BA38: 44
A39: 38 | B39: Colby Parkinson | C39: 25 | D39: 34 | E39: 247 | F39: 5 | G39: 2 | H39: 0 | I39: 0 | J39: 17 | K39: 61.7 | L39: LAR | M39: 37 | N39: 25 | O39: 34 | P39: 322 | Q39: 5 | R39: 2 | S39: 0 | T39: 0 | U39: 14 | V39: 69.2 | W39: 89 | X39: 5 | Y39: 8 | Z39: 33 | AA39: 0 | AB39: 0 | AC39: 0 | AD39: 0 | AE39: 6 | AF39: 8.3 | AG39: SEA | AH39: 47.352941 | AI39: 47.352941 | AJ39: SEA | AK39: 42.285714 | AL39: 34.823529 | AM39: SEA | AN39: 32.166667 | AO39: 11.352941 | AP39: 88 | AQ39: 15.9 | AR39: 555 | AS39: 136 | AT39: 24.6 | AU39: 553 | AV39: 97 | AW39: 20.5 | AX39: 473 | AY39: 88 | AZ39: 102 | BA39: 89
